Workbook

Sheet 사용안내
A1: 2027 오믈렛 KPI 팀장 관리 워크북 — 사용안내
A3: 🔗 바로가기
A4: 📊 전사_종합요약 | B4: 📈 Dashboard | C4: 🔬 Research | D4: 🧩 PS | E4: 📈 BD | F4: 🛠 PB | G4: 🏢 BM | H4: 📐 등급·배점기준
A7: ① 이 워크북의 핵심 로직
A8: 과정지표 2종(① 성과=정량 5개 + ② 역량=정성 5개)은 결과지표(50점) 달성을 위해 팀이 마땅히 수행해야 할 선행 활동입니다.
A11: ② 왜 각 지표를 5개로 고정했는가
A12: 초기 스타트업 단계에서 KPI가 성공적으로 정착하려면 관리 포인트가 단순해야 합니다. 5개를 넘기면 팀장도 팀원도 무엇에 집중해야 할지 흐려지므로, 개별성과·역량평가 모두 각 5개 항목으로 고정합니다.
A15: ③ Research·PS 고정 항목 안내 (대표이사 원칙)
A16: "PS는 고객의 문제 해결에 책임지고, Research는 Omelet의 문제 해결 능력을 발전시키는 데 책임진다." 이 원칙에 따라 Research·PS 개별성과 5개 항목 중 1~2번은 대표이사 원칙을 반영해 고정했습니다(하늘색 셀, 수정 불가). 3~5번 및 BD/PB/BM의 5개 항목은 전부 팀장이 직접 설정합니다(노란 셀).
A19: 팀 | B19: 번호 | C19: 고정 항목명 | D19: 측정 지표(건수 기준)
A20: Research | B20: 1 | C20: Capability Gap 발굴 & Technical Advancement | D20: 신규 리서치 문제 정의 건수 + 벤치마크 성능 개선 건수
A21: Research | B21: 2 | C21: Rigorous Validation & Transfer/Adoption | D21: 재현 가능한 검증 리포트 건수 + PS/PB/Solver/OCP 이관 완료 건수
A22: PS | B22: 1 | C22: Problem Definition & Solution Quality | D22: 고객 문제정의서·솔루션 설계서 작성 및 내부 승인 완료 건수
A23: PS | B23: 2 | C23: Business Impact & Adoption | D23: 고객 운영 반영(PoC→정식 도입) 및 성과 측정 보고 완료 건수
A25: ④ 작성 순서
A26: 1단계. 위 바로가기에서 본인 팀 시트로 이동합니다. 시트 안에는 ①결과지표 ②개별성과 ③역량평가+종합 표가 위→아래로 있습니다.
A27: 2단계. ①결과지표 표의 팀리더 행에 이름을 입력하고 팀 목표(연간 건수 등)를 확인·조정합니다. 이 이름은 ②③표에도 자동 반영됩니다.
A28: 3단계. ②개별성과 표에서 3~5번 항목명을 팀 고유 KPI로 설정하고(Research/PS는 1~2번 고정), 팀원별 목표·실적을 입력합니다.
A29: 4단계. ③역량평가 표에 팀원별 점수(0~6점)를 입력합니다. 리더 본인의 역량은 상급자가 별도 평가합니다.
A30: 5단계. 노란 셀만 입력하면 회색 셀(점수·등급·보상)은 자동 계산됩니다. ③표 우측의 종합점수·등급·보상을 확인하고, 전사_종합요약 시트에서 전체 결과를 확인합니다.
A32: ⑤ 셀 색상 범례
B33: 입력용 (팀장이 직접 채우는 셀)
B34: 자동 계산 수식 — 특별한 사유가 없다면 값을 직접 덮어쓰지 마세요(수식이 사라집니다)
B35: 고정 항목 — 대표이사 원칙 반영 항목. 임의로 바꾸지 말고 변경이 필요하면 관리자와 협의하세요
B36: 팀리더 전용 안내 문구
A37: 이 버전(version02)은 시트 잠금을 해제해 모든 셀을 자유롭게 수정할 수 있습니다. 다만 회색(자동계산)·하늘색(고정) 셀을 실수로 고치면 수식이 깨지거나 원칙에 어긋날 수 있으니, 위 색상 범례를 참고해 노란 셀 위주로 입력해 주세요.
A40: ⑥ 표가 3개로 나뉜 이유
A41: 결과지표·개별성과·역량평가를 한 표에 가로로 이어붙이면 항목이 많아 옆으로 스크롤하기 어렵습니다. 그래서 지표 그룹별로 표 3개(①②③)를 위→아래로 나누어 배치했습니다. 이름·직책은 ①표에만 입력하면 ②③표에 수식으로 자동 반영되므로 3번 다시 입력할 필요가 없습니다.
A44: 등급 컷오프·보상 매핑 상세는 '등급·배점기준' 시트를 참고하세요 →
A46: 문의: KPI 거버넌스 담당(553_orchestrator_kpi-governance-agent)

Sheet 전사_종합요약
A1: 📊 전사 종합요약 — 전 직원 결과·과정·종합 현황
A2: 🏠 사용안내로 이동 | E2: 📈 Dashboard 보기
A3: No | B3: 팀 | C3: 성명 | D3: 직책 | E3: 결과지표 (50) | F3: 개별성과 (20) | G3: 역량평가 (30) | H3: 종합점수 (100) | I3: 종합등급 | J3: 보상구분
A4: 1 | B4: Research | C4: =Research!A50 | D4: =Research!B50 | E4: =Research!J50 | F4: 해당없음 | G4: 상급자 평가 | H4: - | I4: - | J4: 리더 별도 산정
A5: 2 | B5: Research | C5: =Research!A51 | D5: =Research!B51 | E5: =Research!J51 | F5: =Research!K51 | G5: =Research!H51 | H5: =Research!L51 | I5: =Research!M51 | J5: =Research!N51
A6: 3 | B6: Research | C6: =Research!A52 | D6: =Research!B52 | E6: =Research!J52 | F6: =Research!K52 | G6: =Research!H52 | H6: =Research!L52 | I6: =Research!M52 | J6: =Research!N52
A7: 4 | B7: Research | C7: =Research!A53 | D7: =Research!B53 | E7: =Research!J53 | F7: =Research!K53 | G7: =Research!H53 | H7: =Research!L53 | I7: =Research!M53 | J7: =Research!N53
A8: 5 | B8: Research | C8: =Research!A54 | D8: =Research!B54 | E8: =Research!J54 | F8: =Research!K54 | G8: =Research!H54 | H8: =Research!L54 | I8: =Research!M54 | J8: =Research!N54
A9: 6 | B9: Research | C9: =Research!A55 | D9: =Research!B55 | E9: =Research!J55 | F9: =Research!K55 | G9: =Research!H55 | H9: =Research!L55 | I9: =Research!M55 | J9: =Research!N55
A10: 7 | B10: Research | C10: =Research!A56 | D10: =Research!B56 | E10: =Research!J56 | F10: =Research!K56 | G10: =Research!H56 | H10: =Research!L56 | I10: =Research!M56 | J10: =Research!N56
A11: 8 | B11: Research | C11: =Research!A57 | D11: =Research!B57 | E11: =Research!J57 | F11: =Research!K57 | G11: =Research!H57 | H11: =Research!L57 | I11: =Research!M57 | J11: =Research!N57
A12: 9 | B12: Research | C12: =Research!A58 | D12: =Research!B58 | E12: =Research!J58 | F12: =Research!K58 | G12: =Research!H58 | H12: =Research!L58 | I12: =Research!M58 | J12: =Research!N58
A13: 10 | B13: Research | C13: =Research!A59 | D13: =Research!B59 | E13: =Research!J59 | F13: =Research!K59 | G13: =Research!H59 | H13: =Research!L59 | I13: =Research!M59 | J13: =Research!N59
A14: 11 | B14: Research | C14: =Research!A60 | D14: =Research!B60 | E14: =Research!J60 | F14: =Research!K60 | G14: =Research!H60 | H14: =Research!L60 | I14: =Research!M60 | J14: =Research!N60
A15: 12 | B15: Research | C15: =Research!A61 | D15: =Research!B61 | E15: =Research!J61 | F15: =Research!K61 | G15: =Research!H61 | H15: =Research!L61 | I15: =Research!M61 | J15: =Research!N61
A16: 13 | B16: Research | C16: =Research!A62 | D16: =Research!B62 | E16: =Research!J62 | F16: =Research!K62 | G16: =Research!H62 | H16: =Research!L62 | I16: =Research!M62 | J16: =Research!N62
... A19: 16 | B19: Research | C19: =Research!A65 | D19: =Research!B65 | E19: =Research!J65 | F19: =Research!K65 | G19: =Research!H65 | H19: =Research!L65 | I19: =Research!M65 | J19: =Research!N65
A20: 17 | B20: PS | C20: =PS!A50 | D20: =PS!B50 | E20: =PS!J50 | F20: 해당없음 | G20: 상급자 평가 | H20: - | I20: - | J20: 리더 별도 산정
A21: 18 | B21: PS | C21: =PS!A51 | D21: =PS!B51 | E21: =PS!J51 | F21: =PS!K51 | G21: =PS!H51 | H21: =PS!L51 | I21: =PS!M51 | J21: =PS!N51
A22: 19 | B22: PS | C22: =PS!A52 | D22: =PS!B52 | E22: =PS!J52 | F22: =PS!K52 | G22: =PS!H52 | H22: =PS!L52 | I22: =PS!M52 | J22: =PS!N52
A23: 20 | B23: PS | C23: =PS!A53 | D23: =PS!B53 | E23: =PS!J53 | F23: =PS!K53 | G23: =PS!H53 | H23: =PS!L53 | I23: =PS!M53 | J23: =PS!N53
A24: 21 | B24: PS | C24: =PS!A54 | D24: =PS!B54 | E24: =PS!J54 | F24: =PS!K54 | G24: =PS!H54 | H24: =PS!L54 | I24: =PS!M54 | J24: =PS!N54
A25: 22 | B25: PS | C25: =PS!A55 | D25: =PS!B55 | E25: =PS!J55 | F25: =PS!K55 | G25: =PS!H55 | H25: =PS!L55 | I25: =PS!M55 | J25: =PS!N55
A26: 23 | B26: PS | C26: =PS!A56 | D26: =PS!B56 | E26: =PS!J56 | F26: =PS!K56 | G26: =PS!H56 | H26: =PS!L56 | I26: =PS!M56 | J26: =PS!N56
A27: 24 | B27: PS | C27: =PS!A57 | D27: =PS!B57 | E27: =PS!J57 | F27: =PS!K57 | G27: =PS!H57 | H27: =PS!L57 | I27: =PS!M57 | J27: =PS!N57
A28: 25 | B28: PS | C28: =PS!A58 | D28: =PS!B58 | E28: =PS!J58 | F28: =PS!K58 | G28: =PS!H58 | H28: =PS!L58 | I28: =PS!M58 | J28: =PS!N58
A29: 26 | B29: PS | C29: =PS!A59 | D29: =PS!B59 | E29: =PS!J59 | F29: =PS!K59 | G29: =PS!H59 | H29: =PS!L59 | I29: =PS!M59 | J29: =PS!N59
A30: 27 | B30: PS | C30: =PS!A60 | D30: =PS!B60 | E30: =PS!J60 | F30: =PS!K60 | G30: =PS!H60 | H30: =PS!L60 | I30: =PS!M60 | J30: =PS!N60
A31: 28 | B31: PS | C31: =PS!A61 | D31: =PS!B61 | E31: =PS!J61 | F31: =PS!K61 | G31: =PS!H61 | H31: =PS!L61 | I31: =PS!M61 | J31: =PS!N61
A32: 29 | B32: PS | C32: =PS!A62 | D32: =PS!B62 | E32: =PS!J62 | F32: =PS!K62 | G32: =PS!H62 | H32: =PS!L62 | I32: =PS!M62 | J32: =PS!N62
... A35: 32 | B35: PS | C35: =PS!A65 | D35: =PS!B65 | E35: =PS!J65 | F35: =PS!K65 | G35: =PS!H65 | H35: =PS!L65 | I35: =PS!M65 | J35: =PS!N65
A36: 33 | B36: BD | C36: =BD!A50 | D36: =BD!B50 | E36: =BD!J50 | F36: 해당없음 | G36: 상급자 평가 | H36: - | I36: - | J36: 리더 별도 산정
A37: 34 | B37: BD | C37: =BD!A51 | D37: =BD!B51 | E37: =BD!J51 | F37: =BD!K51 | G37: =BD!H51 | H37: =BD!L51 | I37: =BD!M51 | J37: =BD!N51
A38: 35 | B38: BD | C38: =BD!A52 | D38: =BD!B52 | E38: =BD!J52 | F38: =BD!K52 | G38: =BD!H52 | H38: =BD!L52 | I38: =BD!M52 | J38: =BD!N52
A39: 36 | B39: BD | C39: =BD!A53 | D39: =BD!B53 | E39: =BD!J53 | F39: =BD!K53 | G39: =BD!H53 | H39: =BD!L53 | I39: =BD!M53 | J39: =BD!N53
A40: 37 | B40: BD | C40: =BD!A54 | D40: =BD!B54 | E40: =BD!J54 | F40: =BD!K54 | G40: =BD!H54 | H40: =BD!L54 | I40: =BD!M54 | J40: =BD!N54
A41: 38 | B41: BD | C41: =BD!A55 | D41: =BD!B55 | E41: =BD!J55 | F41: =BD!K55 | G41: =BD!H55 | H41: =BD!L55 | I41: =BD!M55 | J41: =BD!N55
A42: 39 | B42: BD | C42: =BD!A56 | D42: =BD!B56 | E42: =BD!J56 | F42: =BD!K56 | G42: =BD!H56 | H42: =BD!L56 | I42: =BD!M56 | J42: =BD!N56
A43: 40 | B43: BD | C43: =BD!A57 | D43: =BD!B57 | E43: =BD!J57 | F43: =BD!K57 | G43: =BD!H57 | H43: =BD!L57 | I43: =BD!M57 | J43: =BD!N57
A44: 41 | B44: BD | C44: =BD!A58 | D44: =BD!B58 | E44: =BD!J58 | F44: =BD!K58 | G44: =BD!H58 | H44: =BD!L58 | I44: =BD!M58 | J44: =BD!N58
...

Sheet Dashboard
A1: 📈 Dashboard — 전사 KPI 현황 (자동 연동, 실시간 계산)
A2: 🏠 사용안내로 이동 | E2: 📊 전사_종합요약 보기
A4: 전사 평균 종합점수 | D4: 등록된 인원 수 | G4: S등급 인원 | J4: D등급 인원(PIP 대상)
A5: =전사_종합요약!H84 | D5: =COUNTIF(전사_종합요약!$C$4:$C$83,"?*") | G5: =COUNTIF(전사_종합요약!$I$4:$I$83,"S") | J5: =COUNTIF(전사_종합요약!$I$4:$I$83,"D")
A7: 📎 차트 원본 데이터 (자동계산 — 수정하지 마세요)
A8: 팀 | B8: 결과지표 평균 | C8: 개별성과 평균 | D8: 역량평가 평균 | E8: 종합점수 평균 | F8: 등록 인원수 | H8: 등급 | I8: 인원수
A9: Research | B9: =AVERAGEIF(전사_종합요약!$B$4:$B$83,A9,전사_종합요약!$E$4:$E$83) | C9: =AVERAGEIF(전사_종합요약!$B$4:$B$83,A9,전사_종합요약!$F$4:$F$83) | D9: =AVERAGEIF(전사_종합요약!$B$4:$B$83,A9,전사_종합요약!$G$4:$G$83) | E9: =AVERAGEIF(전사_종합요약!$B$4:$B$83,A9,전사_종합요약!$H$4:$H$83) | F9: =COUNTIFS(전사_종합요약!$B$4:$B$83,A9,전사_종합요약!$C$4:$C$83,"?*") | H9: S | I9: =COUNTIF(전사_종합요약!$I$4:$I$83,"S")
A10: PS | B10: =AVERAGEIF(전사_종합요약!$B$4:$B$83,A10,전사_종합요약!$E$4:$E$83) | C10: =AVERAGEIF(전사_종합요약!$B$4:$B$83,A10,전사_종합요약!$F$4:$F$83) | D10: =AVERAGEIF(전사_종합요약!$B$4:$B$83,A10,전사_종합요약!$G$4:$G$83) | E10: =AVERAGEIF(전사_종합요약!$B$4:$B$83,A10,전사_종합요약!$H$4:$H$83) | F10: =COUNTIFS(전사_종합요약!$B$4:$B$83,A10,전사_종합요약!$C$4:$C$83,"?*") | H10: A | I10: =COUNTIF(전사_종합요약!$I$4:$I$83,"A")
A11: BD | B11: =AVERAGEIF(전사_종합요약!$B$4:$B$83,A11,전사_종합요약!$E$4:$E$83) | C11: =AVERAGEIF(전사_종합요약!$B$4:$B$83,A11,전사_종합요약!$F$4:$F$83) | D11: =AVERAGEIF(전사_종합요약!$B$4:$B$83,A11,전사_종합요약!$G$4:$G$83) | E11: =AVERAGEIF(전사_종합요약!$B$4:$B$83,A11,전사_종합요약!$H$4:$H$83) | F11: =COUNTIFS(전사_종합요약!$B$4:$B$83,A11,전사_종합요약!$C$4:$C$83,"?*") | H11: B | I11: =COUNTIF(전사_종합요약!$I$4:$I$83,"B")
A12: PB | B12: =AVERAGEIF(전사_종합요약!$B$4:$B$83,A12,전사_종합요약!$E$4:$E$83) | C12: =AVERAGEIF(전사_종합요약!$B$4:$B$83,A12,전사_종합요약!$F$4:$F$83) | D12: =AVERAGEIF(전사_종합요약!$B$4:$B$83,A12,전사_종합요약!$G$4:$G$83) | E12: =AVERAGEIF(전사_종합요약!$B$4:$B$83,A12,전사_종합요약!$H$4:$H$83) | F12: =COUNTIFS(전사_종합요약!$B$4:$B$83,A12,전사_종합요약!$C$4:$C$83,"?*") | H12: C | I12: =COUNTIF(전사_종합요약!$I$4:$I$83,"C")
A13: BM | B13: =AVERAGEIF(전사_종합요약!$B$4:$B$83,A13,전사_종합요약!$E$4:$E$83) | C13: =AVERAGEIF(전사_종합요약!$B$4:$B$83,A13,전사_종합요약!$F$4:$F$83) | D13: =AVERAGEIF(전사_종합요약!$B$4:$B$83,A13,전사_종합요약!$G$4:$G$83) | E13: =AVERAGEIF(전사_종합요약!$B$4:$B$83,A13,전사_종합요약!$H$4:$H$83) | F13: =COUNTIFS(전사_종합요약!$B$4:$B$83,A13,전사_종합요약!$C$4:$C$83,"?*") | H13: D | I13: =COUNTIF(전사_종합요약!$I$4:$I$83,"D")

Sheet Research
A1: 🏠 사용안내로 이동 | E1: 📊 전사 종합요약 보기
A2: Research — Omelet의 Problem-Solving Capability 발전에 책임 | ✏️ 이 시트는 잠금이 해제되어 모든 셀을 수정할 수 있습니다. 노란 셀=입력용, 회색 셀=자동계산 수식, 하늘색 셀=고정 항목이니 참고해서 편집하세요. ①결과지표 ②개별성과 ③역량평가+종합 표가 위에서 아래로 나열되어 있으며, 이름·직책은 ①표에 입력하면 ②③표에 자동으로 채워집니다(직접 고쳐도 되지만 그러면 자동연동이 끊깁니다).
A4: ① 결과지표 · 팀 공동 (50점)
A5: 이름 | B5: 직책 | C5: 실적 | D5: 목표 | E5: 달성률 | F5: 점수 (50) | G5: 등급
A6: 홍길동(예시) | B6: 팀리더 | C6: =SUM(C7:C21) | D6: 5 | E6: =IF(D6=0,"",C6/D6) | F6: =IF(E6="","",MIN(E6*50,50)) | G6: =IF(F6="","",_xlfn.IFS(F6>=48,"S",F6>=45,"A",F6>=42,"B",F6>=38,"C",TRUE,"D"))
A7: 김하나(예시) | B7: 팀원 | C7: 6 | D7: 5 | E7: =IF(OR(A7="",D7=""),"",C7/D7) | F7: =IF(A7="","",F6) | G7: =IF(A7="","",G6)
A8: 이몽룡(예시) | B8: 팀원 | C8: 5 | D8: 5 | E8: =IF(OR(A8="",D8=""),"",C8/D8) | F8: =IF(A8="","",F6) | G8: =IF(A8="","",G6)
A9: 박문수(예시) | B9: 팀원 | C9: 5 | D9: 5 | E9: =IF(OR(A9="",D9=""),"",C9/D9) | F9: =IF(A9="","",F6) | G9: =IF(A9="","",G6)
A10: 최유리(예시) | B10: 팀원 | C10: 4 | D10: 5 | E10: =IF(OR(A10="",D10=""),"",C10/D10) | F10: =IF(A10="","",F6) | G10: =IF(A10="","",G6)
A11: 정다솜(예시) | B11: 팀원 | C11: 4 | D11: 5 | E11: =IF(OR(A11="",D11=""),"",C11/D11) | F11: =IF(A11="","",F6) | G11: =IF(A11="","",G6)
A12: 강도윤(예시) | B12: 팀원 | C12: 4 | D12: 5 | E12: =IF(OR(A12="",D12=""),"",C12/D12) | F12: =IF(A12="","",F6) | G12: =IF(A12="","",G6)
A13: 윤서연(예시) | B13: 팀원 | C13: 3 | D13: 5 | E13: =IF(OR(A13="",D13=""),"",C13/D13) | F13: =IF(A13="","",F6) | G13: =IF(A13="","",G6)
A14: 임하은(예시) | B14: 팀원 | C14: 3 | D14: 5 | E14: =IF(OR(A14="",D14=""),"",C14/D14) | F14: =IF(A14="","",F6) | G14: =IF(A14="","",G6)
A15: 조지훈(예시) | B15: 팀원 | C15: 2 | D15: 5 | E15: =IF(OR(A15="",D15=""),"",C15/D15) | F15: =IF(A15="","",F6) | G15: =IF(A15="","",G6)
A16: 한수아(예시) | B16: 팀원 | C16: 2 | D16: 5 | E16: =IF(OR(A16="",D16=""),"",C16/D16) | F16: =IF(A16="","",F6) | G16: =IF(A16="","",G6)
B17: 팀원 | E17: =IF(OR(A17="",D17=""),"",C17/D17) | F17: =IF(A17="","",F6) | G17: =IF(A17="","",G6)
B18: 팀원 | E18: =IF(OR(A18="",D18=""),"",C18/D18) | F18: =IF(A18="","",F6) | G18: =IF(A18="","",G6)
B19: 팀원 | E19: =IF(OR(A19="",D19=""),"",C19/D19) | F19: =IF(A19="","",F6) | G19: =IF(A19="","",G6)
B20: 팀원 | E20: =IF(OR(A20="",D20=""),"",C20/D20) | F20: =IF(A20="","",F6) | G20: =IF(A20="","",G6)
B21: 팀원 | E21: =IF(OR(A21="",D21=""),"",C21/D21) | F21: =IF(A21="","",F6) | G21: =IF(A21="","",G6)
A22: 팀 평균 / 합계 | C22: =SUM(C7:C21) | D22: - | E22: - | F22: =F6 | G22: =G6
A24: ② 개별성과 · 정량 (과정지표Ⅰ, 20점)
A25: 이름 (①표 자동) | B25: 직책 (①표 자동) | C25: 1. Capability Gap 발굴 & Technical Advancement | F25: 2. Rigorous Validation & Transfer/Adoption | I25: 3. (예시) 알고리즘 모듈 개발 | L25: 4. (예시) PB 기술자문 지원 | O25: 5. (예시) 기술문서 자산화 | R25: 소계 (20) | S25: 등급
C26: [대표 원칙 고정] 신규 리서치 문제 정의 건수 + 벤치마크 성능 개선 건수를 합산 관리 계산 예시: 실적 4건 ÷ 목표 5건 × 4점 = 3.2점 | F26: [대표 원칙 고정] 재현 가능한 검증 리포트 건수 + PS/PB/Solver/OCP 이관 완료 건수 계산 예시: 실적 3건 ÷ 목표 4건 × 4점 = 3.0점 | I26: 이 항목명은 예시입니다. 팀 고유 KPI로 교체하세요. 계산식 예시: 실적 ÷ 목표 × 4점 = 점수 | L26: 이 항목명은 예시입니다. 팀 고유 KPI로 교체하세요. 계산식 예시: 실적 ÷ 목표 × 4점 = 점수 | O26: 이 항목명은 예시입니다. 팀 고유 KPI로 교체하세요. 계산식 예시: 실적 ÷ 목표 × 4점 = 점수
C27: 실적 | D27: 목표 | E27: 점수 (4) | F27: 실적 | G27: 목표 | H27: 점수 (4) | I27: 실적 | J27: 목표 | K27: 점수 (4) | L27: 실적 | M27: 목표 | N27: 점수 (4) | O27: 실적 | P27: 목표 | Q27: 점수 (4)
A28: =IF(A6="","",A6) | B28: =B6 | C28: 팀리더는 개별성과(정량) 항목 해당 없음 — 팀 결과지표·역량평가 중심으로 평가
A29: =IF(A7="","",A7) | B29: =B7 | C29: 6 | D29: 5 | E29: =IF(OR(A29="",D29="",D29=0),"",MIN(C29/D29*4,4)) | F29: 4 | G29: 4 | H29: =IF(OR(A29="",G29="",G29=0),"",MIN(F29/G29*4,4)) | I29: 4 | J29: 4 | K29: =IF(OR(A29="",J29="",J29=0),"",MIN(I29/J29*4,4)) | L29: 4 | M29: 4 | N29: =IF(OR(A29="",M29="",M29=0),"",MIN(L29/M29*4,4)) | O29: 3 | P29: 3 | Q29: =IF(OR(A29="",P29="",P29=0),"",MIN(O29/P29*4,4)) | R29: =IF(A29="","",SUM(E29,H29,K29,N29,Q29)) | S29: =IF(R29="","",_xlfn.IFS(R29>=18,"S",R29>=16,"A",R29>=14,"B",R29>=11,"C",TRUE,"D"))
A30: =IF(A8="","",A8) | B30: =B8 | C30: 5 | D30: 5 | E30: =IF(OR(A30="",D30="",D30=0),"",MIN(C30/D30*4,4)) | F30: 4 | G30: 4 | H30: =IF(OR(A30="",G30="",G30=0),"",MIN(F30/G30*4,4)) | I30: 4 | J30: 4 | K30: =IF(OR(A30="",J30="",J30=0),"",MIN(I30/J30*4,4)) | L30: 4 | M30: 4 | N30: =IF(OR(A30="",M30="",M30=0),"",MIN(L30/M30*4,4)) | O30: 3 | P30: 3 | Q30: =IF(OR(A30="",P30="",P30=0),"",MIN(O30/P30*4,4)) | R30: =IF(A30="","",SUM(E30,H30,K30,N30,Q30)) | S30: =IF(R30="","",_xlfn.IFS(R30>=18,"S",R30>=16,"A",R30>=14,"B",R30>=11,"C",TRUE,"D"))
A31: =IF(A9="","",A9) | B31: =B9 | C31: 5 | D31: 5 | E31: =IF(OR(A31="",D31="",D31=0),"",MIN(C31/D31*4,4)) | F31: 4 | G31: 4 | H31: =IF(OR(A31="",G31="",G31=0),"",MIN(F31/G31*4,4)) | I31: 4 | J31: 4 | K31: =IF(OR(A31="",J31="",J31=0),"",MIN(I31/J31*4,4)) | L31: 4 | M31: 4 | N31: =IF(OR(A31="",M31="",M31=0),"",MIN(L31/M31*4,4)) | O31: 3 | P31: 3 | Q31: =IF(OR(A31="",P31="",P31=0),"",MIN(O31/P31*4,4)) | R31: =IF(A31="","",SUM(E31,H31,K31,N31,Q31)) | S31: =IF(R31="","",_xlfn.IFS(R31>=18,"S",R31>=16,"A",R31>=14,"B",R31>=11,"C",TRUE,"D"))
A32: =IF(A10="","",A10) | B32: =B10 | C32: 4 | D32: 5 | E32: =IF(OR(A32="",D32="",D32=0),"",MIN(C32/D32*4,4)) | F32: 3 | G32: 4 | H32: =IF(OR(A32="",G32="",G32=0),"",MIN(F32/G32*4,4)) | I32: 3 | J32: 4 | K32: =IF(OR(A32="",J32="",J32=0),"",MIN(I32/J32*4,4)) | L32: 3 | M32: 4 | N32: =IF(OR(A32="",M32="",M32=0),"",MIN(L32/M32*4,4)) | O32: 3 | P32: 3 | Q32: =IF(OR(A32="",P32="",P32=0),"",MIN(O32/P32*4,4)) | R32: =IF(A32="","",SUM(E32,H32,K32,N32,Q32)) | S32: =IF(R32="","",_xlfn.IFS(R32>=18,"S",R32>=16,"A",R32>=14,"B",R32>=11,"C",TRUE,"D"))
A33: =IF(A11="","",A11) | B33: =B11 | C33: 4 | D33: 5 | E33: =IF(OR(A33="",D33="",D33=0),"",MIN(C33/D33*4,4)) | F33: 3 | G33: 4 | H33: =IF(OR(A33="",G33="",G33=0),"",MIN(F33/G33*4,4)) | I33: 3 | J33: 4 | K33: =IF(OR(A33="",J33="",J33=0),"",MIN(I33/J33*4,4)) | L33: 3 | M33: 4 | N33: =IF(OR(A33="",M33="",M33=0),"",MIN(L33/M33*4,4)) | O33: 2 | P33: 3 | Q33: =IF(OR(A33="",P33="",P33=0),"",MIN(O33/P33*4,4)) | R33: =IF(A33="","",SUM(E33,H33,K33,N33,Q33)) | S33: =IF(R33="","",_xlfn.IFS(R33>=18,"S",R33>=16,"A",R33>=14,"B",R33>=11,"C",TRUE,"D"))
A34: =IF(A12="","",A12) | B34: =B12 | C34: 4 | D34: 5 | E34: =IF(OR(A34="",D34="",D34=0),"",MIN(C34/D34*4,4)) | F34: 3 | G34: 4 | H34: =IF(OR(A34="",G34="",G34=0),"",MIN(F34/G34*4,4)) | I34: 3 | J34: 4 | K34: =IF(OR(A34="",J34="",J34=0),"",MIN(I34/J34*4,4)) | L34: 3 | M34: 4 | N34: =IF(OR(A34="",M34="",M34=0),"",MIN(L34/M34*4,4)) | O34: 2 | P34: 3 | Q34: =IF(OR(A34="",P34="",P34=0),"",MIN(O34/P34*4,4)) | R34: =IF(A34="","",SUM(E34,H34,K34,N34,Q34)) | S34: =IF(R34="","",_xlfn.IFS(R34>=18,"S",R34>=16,"A",R34>=14,"B",R34>=11,"C",TRUE,"D"))
A35: =IF(A13="","",A13) | B35: =B13 | C35: 3 | D35: 5 | E35: =IF(OR(A35="",D35="",D35=0),"",MIN(C35/D35*4,4)) | F35: 2 | G35: 4 | H35: =IF(OR(A35="",G35="",G35=0),"",MIN(F35/G35*4,4)) | I35: 2 | J35: 4 | K35: =IF(OR(A35="",J35="",J35=0),"",MIN(I35/J35*4,4)) | L35: 2 | M35: 4 | N35: =IF(OR(A35="",M35="",M35=0),"",MIN(L35/M35*4,4)) | O35: 2 | P35: 3 | Q35: =IF(OR(A35="",P35="",P35=0),"",MIN(O35/P35*4,4)) | R35: =IF(A35="","",SUM(E35,H35,K35,N35,Q35)) | S35: =IF(R35="","",_xlfn.IFS(R35>=18,"S",R35>=16,"A",R35>=14,"B",R35>=11,"C",TRUE,"D"))
A36: =IF(A14="","",A14) | B36: =B14 | C36: 3 | D36: 5 | E36: =IF(OR(A36="",D36="",D36=0),"",MIN(C36/D36*4,4)) | F36: 2 | G36: 4 | H36: =IF(OR(A36="",G36="",G36=0),"",MIN(F36/G36*4,4)) | I36: 2 | J36: 4 | K36: =IF(OR(A36="",J36="",J36=0),"",MIN(I36/J36*4,4)) | L36: 2 | M36: 4 | N36: =IF(OR(A36="",M36="",M36=0),"",MIN(L36/M36*4,4)) | O36: 2 | P36: 3 | Q36: =IF(OR(A36="",P36="",P36=0),"",MIN(O36/P36*4,4)) | R36: =IF(A36="","",SUM(E36,H36,K36,N36,Q36)) | S36: =IF(R36="","",_xlfn.IFS(R36>=18,"S",R36>=16,"A",R36>=14,"B",R36>=11,"C",TRUE,"D"))
A37: =IF(A15="","",A15) | B37: =B15 | C37: 2 | D37: 5 | E37: =IF(OR(A37="",D37="",D37=0),"",MIN(C37/D37*4,4)) | F37: 2 | G37: 4 | H37: =IF(OR(A37="",G37="",G37=0),"",MIN(F37/G37*4,4)) | I37: 2 | J37: 4 | K37: =IF(OR(A37="",J37="",J37=0),"",MIN(I37/J37*4,4)) | L37: 2 | M37: 4 | N37: =IF(OR(A37="",M37="",M37=0),"",MIN(L37/M37*4,4)) | O37: 1 | P37: 3 | Q37: =IF(OR(A37="",P37="",P37=0),"",MIN(O37/P37*4,4)) | R37: =IF(A37="","",SUM(E37,H37,K37,N37,Q37)) | S37: =IF(R37="","",_xlfn.IFS(R37>=18,"S",R37>=16,"A",R37>=14,"B",R37>=11,"C",TRUE,"D"))
A38: =IF(A16="","",A16) | B38: =B16 | C38: 2 | D38: 5 | E38: =IF(OR(A38="",D38="",D38=0),"",MIN(C38/D38*4,4)) | F38: 1 | G38: 4 | H38: =IF(OR(A38="",G38="",G38=0),"",MIN(F38/G38*4,4)) | I38: 1 | J38: 4 | K38: =IF(OR(A38="",J38="",J38=0),"",MIN(I38/J38*4,4)) | L38: 1 | M38: 4 | N38: =IF(OR(A38="",M38="",M38=0),"",MIN(L38/M38*4,4)) | O38: 1 | P38: 3 | Q38: =IF(OR(A38="",P38="",P38=0),"",MIN(O38/P38*4,4)) | R38: =IF(A38="","",SUM(E38,H38,K38,N38,Q38)) | S38: =IF(R38="","",_xlfn.IFS(R38>=18,"S",R38>=16,"A",R38>=14,"B",R38>=11,"C",TRUE,"D"))
A39: =IF(A17="","",A17) | B39: =B17 | E39: =IF(OR(A39="",D39="",D39=0),"",MIN(C39/D39*4,4)) | H39: =IF(OR(A39="",G39="",G39=0),"",MIN(F39/G39*4,4)) | K39: =IF(OR(A39="",J39="",J39=0),"",MIN(I39/J39*4,4)) | N39: =IF(OR(A39="",M39="",M39=0),"",MIN(L39/M39*4,4)) | Q39: =IF(OR(A39="",P39="",P39=0),"",MIN(O39/P39*4,4)) | R39: =IF(A39="","",SUM(E39,H39,K39,N39,Q39)) | S39: =IF(R39="","",_xlfn.IFS(R39>=18,"S",R39>=16,"A",R39>=14,"B",R39>=11,"C",TRUE,"D"))
A40: =IF(A18="","",A18) | B40: =B18 | E40: =IF(OR(A40="",D40="",D40=0),"",MIN(C40/D40*4,4)) | H40: =IF(OR(A40="",G40="",G40=0),"",MIN(F40/G40*4,4)) | K40: =IF(OR(A40="",J40="",J40=0),"",MIN(I40/J40*4,4)) | N40: =IF(OR(A40="",M40="",M40=0),"",MIN(L40/M40*4,4)) | Q40: =IF(OR(A40="",P40="",P40=0),"",MIN(O40/P40*4,4)) | R40: =IF(A40="","",SUM(E40,H40,K40,N40,Q40)) | S40: =IF(R40="","",_xlfn.IFS(R40>=18,"S",R40>=16,"A",R40>=14,"B",R40>=11,"C",TRUE,"D"))
A41: =IF(A19="","",A19) | B41: =B19 | E41: =IF(OR(A41="",D41="",D41=0),"",MIN(C41/D41*4,4)) | H41: =IF(OR(A41="",G41="",G41=0),"",MIN(F41/G41*4,4)) | K41: =IF(OR(A41="",J41="",J41=0),"",MIN(I41/J41*4,4)) | N41: =IF(OR(A41="",M41="",M41=0),"",MIN(L41/M41*4,4)) | Q41: =IF(OR(A41="",P41="",P41=0),"",MIN(O41/P41*4,4)) | R41: =IF(A41="","",SUM(E41,H41,K41,N41,Q41)) | S41: =IF(R41="","",_xlfn.IFS(R41>=18,"S",R41>=16,"A",R41>=14,"B",R41>=11,"C",TRUE,"D"))
A42: =IF(A20="","",A20) | B42: =B20 | E42: =IF(OR(A42="",D42="",D42=0),"",MIN(C42/D42*4,4)) | H42: =IF(OR(A42="",G42="",G42=0),"",MIN(F42/G42*4,4)) | K42: =IF(OR(A42="",J42="",J42=0),"",MIN(I42/J42*4,4)) | N42: =IF(OR(A42="",M42="",M42=0),"",MIN(L42/M42*4,4)) | Q42: =IF(OR(A42="",P42="",P42=0),"",MIN(O42/P42*4,4)) | R42: =IF(A42="","",SUM(E42,H42,K42,N42,Q42)) | S42: =IF(R42="","",_xlfn.IFS(R42>=18,"S",R42>=16,"A",R42>=14,"B",R42>=11,"C",TRUE,"D"))
...

Sheet PS
A1: 🏠 사용안내로 이동 | E1: 📊 전사 종합요약 보기
A2: PS (Problem Solver) — 고객의 Operational Problem 해결과 실제 의사결정 개선에 책임 | ✏️ 이 시트는 잠금이 해제되어 모든 셀을 수정할 수 있습니다. 노란 셀=입력용, 회색 셀=자동계산 수식, 하늘색 셀=고정 항목이니 참고해서 편집하세요. ①결과지표 ②개별성과 ③역량평가+종합 표가 위에서 아래로 나열되어 있으며, 이름·직책은 ①표에 입력하면 ②③표에 자동으로 채워집니다(직접 고쳐도 되지만 그러면 자동연동이 끊깁니다).
A4: ① 결과지표 · 팀 공동 (50점)
A5: 이름 | B5: 직책 | C5: 실적 | D5: 목표 | E5: 달성률 | F5: 점수 (50) | G5: 등급
A6: 성춘향(예시) | B6: 팀리더 | C6: =SUM(C7:C21) | D6: 25 | E6: =IF(D6=0,"",C6/D6) | F6: =IF(E6="","",MIN(E6*50,50)) | G6: =IF(F6="","",_xlfn.IFS(F6>=48,"S",F6>=45,"A",F6>=42,"B",F6>=38,"C",TRUE,"D"))
A7: 강산들(예시) | B7: 팀원 | C7: 5 | D7: 5 | E7: =IF(OR(A7="",D7=""),"",C7/D7) | F7: =IF(A7="","",F6) | G7: =IF(A7="","",G6)
A8: 윤슬기(예시) | B8: 팀원 | C8: 5 | D8: 5 | E8: =IF(OR(A8="",D8=""),"",C8/D8) | F8: =IF(A8="","",F6) | G8: =IF(A8="","",G6)
A9: 조은별(예시) | B9: 팀원 | C9: 4 | D9: 5 | E9: =IF(OR(A9="",D9=""),"",C9/D9) | F9: =IF(A9="","",F6) | G9: =IF(A9="","",G6)
A10: 백서윤(예시) | B10: 팀원 | C10: 4 | D10: 5 | E10: =IF(OR(A10="",D10=""),"",C10/D10) | F10: =IF(A10="","",F6) | G10: =IF(A10="","",G6)
A11: 남지호(예시) | B11: 팀원 | C11: 4 | D11: 5 | E11: =IF(OR(A11="",D11=""),"",C11/D11) | F11: =IF(A11="","",F6) | G11: =IF(A11="","",G6)
A12: 문지훈(예시) | B12: 팀원 | C12: 3 | D12: 5 | E12: =IF(OR(A12="",D12=""),"",C12/D12) | F12: =IF(A12="","",F6) | G12: =IF(A12="","",G6)
A13: 손예은(예시) | B13: 팀원 | C13: 3 | D13: 5 | E13: =IF(OR(A13="",D13=""),"",C13/D13) | F13: =IF(A13="","",F6) | G13: =IF(A13="","",G6)
A14: 배승우(예시) | B14: 팀원 | C14: 3 | D14: 5 | E14: =IF(OR(A14="",D14=""),"",C14/D14) | F14: =IF(A14="","",F6) | G14: =IF(A14="","",G6)
A15: 임서현(예시) | B15: 팀원 | C15: 2 | D15: 5 | E15: =IF(OR(A15="",D15=""),"",C15/D15) | F15: =IF(A15="","",F6) | G15: =IF(A15="","",G6)
A16: 곽민재(예시) | B16: 팀원 | C16: 2 | D16: 5 | E16: =IF(OR(A16="",D16=""),"",C16/D16) | F16: =IF(A16="","",F6) | G16: =IF(A16="","",G6)
B17: 팀원 | E17: =IF(OR(A17="",D17=""),"",C17/D17) | F17: =IF(A17="","",F6) | G17: =IF(A17="","",G6)
B18: 팀원 | E18: =IF(OR(A18="",D18=""),"",C18/D18) | F18: =IF(A18="","",F6) | G18: =IF(A18="","",G6)
B19: 팀원 | E19: =IF(OR(A19="",D19=""),"",C19/D19) | F19: =IF(A19="","",F6) | G19: =IF(A19="","",G6)
B20: 팀원 | E20: =IF(OR(A20="",D20=""),"",C20/D20) | F20: =IF(A20="","",F6) | G20: =IF(A20="","",G6)
B21: 팀원 | E21: =IF(OR(A21="",D21=""),"",C21/D21) | F21: =IF(A21="","",F6) | G21: =IF(A21="","",G6)
A22: 팀 평균 / 합계 | C22: =SUM(C7:C21) | D22: - | E22: - | F22: =F6 | G22: =G6
A24: ② 개별성과 · 정량 (과정지표Ⅰ, 20점)
A25: 이름 (①표 자동) | B25: 직책 (①표 자동) | C25: 1. Problem Definition & Solution Quality | F25: 2. Business Impact & Adoption | I25: 3. (예시) 현장실사 지원 | L25: 4. (예시) 기술 PT 지원 | O25: 5. (예시) 수리모델 프로토타입 개발 | R25: 소계 (20) | S25: 등급
C26: [대표 원칙 고정] 고객 문제정의서·솔루션 설계서 작성 및 내부 승인 완료 건수 계산 예시: 실적 8건 ÷ 목표 10건 × 4점 = 3.2점 | F26: [대표 원칙 고정] 고객 운영 반영(PoC→정식 도입) 및 성과 측정 보고 완료 건수 계산 예시: 실적 4건 ÷ 목표 5건 × 4점 = 3.2점 | I26: 이 항목명은 예시입니다. 팀 고유 KPI로 교체하세요. 계산식 예시: 실적 ÷ 목표 × 4점 = 점수 | L26: 이 항목명은 예시입니다. 팀 고유 KPI로 교체하세요. 계산식 예시: 실적 ÷ 목표 × 4점 = 점수 | O26: 이 항목명은 예시입니다. 팀 고유 KPI로 교체하세요. 계산식 예시: 실적 ÷ 목표 × 4점 = 점수
C27: 실적 | D27: 목표 | E27: 점수 (4) | F27: 실적 | G27: 목표 | H27: 점수 (4) | I27: 실적 | J27: 목표 | K27: 점수 (4) | L27: 실적 | M27: 목표 | N27: 점수 (4) | O27: 실적 | P27: 목표 | Q27: 점수 (4)
A28: =IF(A6="","",A6) | B28: =B6 | C28: 팀리더는 개별성과(정량) 항목 해당 없음 — 팀 결과지표·역량평가 중심으로 평가
A29: =IF(A7="","",A7) | B29: =B7 | C29: 10 | D29: 10 | E29: =IF(OR(A29="",D29="",D29=0),"",MIN(C29/D29*4,4)) | F29: 5 | G29: 5 | H29: =IF(OR(A29="",G29="",G29=0),"",MIN(F29/G29*4,4)) | I29: 6 | J29: 6 | K29: =IF(OR(A29="",J29="",J29=0),"",MIN(I29/J29*4,4)) | L29: 3 | M29: 3 | N29: =IF(OR(A29="",M29="",M29=0),"",MIN(L29/M29*4,4)) | O29: 4 | P29: 4 | Q29: =IF(OR(A29="",P29="",P29=0),"",MIN(O29/P29*4,4)) | R29: =IF(A29="","",SUM(E29,H29,K29,N29,Q29)) | S29: =IF(R29="","",_xlfn.IFS(R29>=18,"S",R29>=16,"A",R29>=14,"B",R29>=11,"C",TRUE,"D"))
A30: =IF(A8="","",A8) | B30: =B8 | C30: 9 | D30: 10 | E30: =IF(OR(A30="",D30="",D30=0),"",MIN(C30/D30*4,4)) | F30: 5 | G30: 5 | H30: =IF(OR(A30="",G30="",G30=0),"",MIN(F30/G30*4,4)) | I30: 6 | J30: 6 | K30: =IF(OR(A30="",J30="",J30=0),"",MIN(I30/J30*4,4)) | L30: 3 | M30: 3 | N30: =IF(OR(A30="",M30="",M30=0),"",MIN(L30/M30*4,4)) | O30: 4 | P30: 4 | Q30: =IF(OR(A30="",P30="",P30=0),"",MIN(O30/P30*4,4)) | R30: =IF(A30="","",SUM(E30,H30,K30,N30,Q30)) | S30: =IF(R30="","",_xlfn.IFS(R30>=18,"S",R30>=16,"A",R30>=14,"B",R30>=11,"C",TRUE,"D"))
A31: =IF(A9="","",A9) | B31: =B9 | C31: 9 | D31: 10 | E31: =IF(OR(A31="",D31="",D31=0),"",MIN(C31/D31*4,4)) | F31: 4 | G31: 5 | H31: =IF(OR(A31="",G31="",G31=0),"",MIN(F31/G31*4,4)) | I31: 5 | J31: 6 | K31: =IF(OR(A31="",J31="",J31=0),"",MIN(I31/J31*4,4)) | L31: 3 | M31: 3 | N31: =IF(OR(A31="",M31="",M31=0),"",MIN(L31/M31*4,4)) | O31: 3 | P31: 4 | Q31: =IF(OR(A31="",P31="",P31=0),"",MIN(O31/P31*4,4)) | R31: =IF(A31="","",SUM(E31,H31,K31,N31,Q31)) | S31: =IF(R31="","",_xlfn.IFS(R31>=18,"S",R31>=16,"A",R31>=14,"B",R31>=11,"C",TRUE,"D"))
A32: =IF(A10="","",A10) | B32: =B10 | C32: 8 | D32: 10 | E32: =IF(OR(A32="",D32="",D32=0),"",MIN(C32/D32*4,4)) | F32: 4 | G32: 5 | H32: =IF(OR(A32="",G32="",G32=0),"",MIN(F32/G32*4,4)) | I32: 5 | J32: 6 | K32: =IF(OR(A32="",J32="",J32=0),"",MIN(I32/J32*4,4)) | L32: 2 | M32: 3 | N32: =IF(OR(A32="",M32="",M32=0),"",MIN(L32/M32*4,4)) | O32: 3 | P32: 4 | Q32: =IF(OR(A32="",P32="",P32=0),"",MIN(O32/P32*4,4)) | R32: =IF(A32="","",SUM(E32,H32,K32,N32,Q32)) | S32: =IF(R32="","",_xlfn.IFS(R32>=18,"S",R32>=16,"A",R32>=14,"B",R32>=11,"C",TRUE,"D"))
A33: =IF(A11="","",A11) | B33: =B11 | C33: 7 | D33: 10 | E33: =IF(OR(A33="",D33="",D33=0),"",MIN(C33/D33*4,4)) | F33: 4 | G33: 5 | H33: =IF(OR(A33="",G33="",G33=0),"",MIN(F33/G33*4,4)) | I33: 4 | J33: 6 | K33: =IF(OR(A33="",J33="",J33=0),"",MIN(I33/J33*4,4)) | L33: 2 | M33: 3 | N33: =IF(OR(A33="",M33="",M33=0),"",MIN(L33/M33*4,4)) | O33: 3 | P33: 4 | Q33: =IF(OR(A33="",P33="",P33=0),"",MIN(O33/P33*4,4)) | R33: =IF(A33="","",SUM(E33,H33,K33,N33,Q33)) | S33: =IF(R33="","",_xlfn.IFS(R33>=18,"S",R33>=16,"A",R33>=14,"B",R33>=11,"C",TRUE,"D"))
A34: =IF(A12="","",A12) | B34: =B12 | C34: 7 | D34: 10 | E34: =IF(OR(A34="",D34="",D34=0),"",MIN(C34/D34*4,4)) | F34: 3 | G34: 5 | H34: =IF(OR(A34="",G34="",G34=0),"",MIN(F34/G34*4,4)) | I34: 4 | J34: 6 | K34: =IF(OR(A34="",J34="",J34=0),"",MIN(I34/J34*4,4)) | L34: 2 | M34: 3 | N34: =IF(OR(A34="",M34="",M34=0),"",MIN(L34/M34*4,4)) | O34: 3 | P34: 4 | Q34: =IF(OR(A34="",P34="",P34=0),"",MIN(O34/P34*4,4)) | R34: =IF(A34="","",SUM(E34,H34,K34,N34,Q34)) | S34: =IF(R34="","",_xlfn.IFS(R34>=18,"S",R34>=16,"A",R34>=14,"B",R34>=11,"C",TRUE,"D"))
A35: =IF(A13="","",A13) | B35: =B13 | C35: 6 | D35: 10 | E35: =IF(OR(A35="",D35="",D35=0),"",MIN(C35/D35*4,4)) | F35: 3 | G35: 5 | H35: =IF(OR(A35="",G35="",G35=0),"",MIN(F35/G35*4,4)) | I35: 3 | J35: 6 | K35: =IF(OR(A35="",J35="",J35=0),"",MIN(I35/J35*4,4)) | L35: 2 | M35: 3 | N35: =IF(OR(A35="",M35="",M35=0),"",MIN(L35/M35*4,4)) | O35: 2 | P35: 4 | Q35: =IF(OR(A35="",P35="",P35=0),"",MIN(O35/P35*4,4)) | R35: =IF(A35="","",SUM(E35,H35,K35,N35,Q35)) | S35: =IF(R35="","",_xlfn.IFS(R35>=18,"S",R35>=16,"A",R35>=14,"B",R35>=11,"C",TRUE,"D"))
A36: =IF(A14="","",A14) | B36: =B14 | C36: 5 | D36: 10 | E36: =IF(OR(A36="",D36="",D36=0),"",MIN(C36/D36*4,4)) | F36: 3 | G36: 5 | H36: =IF(OR(A36="",G36="",G36=0),"",MIN(F36/G36*4,4)) | I36: 3 | J36: 6 | K36: =IF(OR(A36="",J36="",J36=0),"",MIN(I36/J36*4,4)) | L36: 2 | M36: 3 | N36: =IF(OR(A36="",M36="",M36=0),"",MIN(L36/M36*4,4)) | O36: 2 | P36: 4 | Q36: =IF(OR(A36="",P36="",P36=0),"",MIN(O36/P36*4,4)) | R36: =IF(A36="","",SUM(E36,H36,K36,N36,Q36)) | S36: =IF(R36="","",_xlfn.IFS(R36>=18,"S",R36>=16,"A",R36>=14,"B",R36>=11,"C",TRUE,"D"))
A37: =IF(A15="","",A15) | B37: =B15 | C37: 4 | D37: 10 | E37: =IF(OR(A37="",D37="",D37=0),"",MIN(C37/D37*4,4)) | F37: 2 | G37: 5 | H37: =IF(OR(A37="",G37="",G37=0),"",MIN(F37/G37*4,4)) | I37: 3 | J37: 6 | K37: =IF(OR(A37="",J37="",J37=0),"",MIN(I37/J37*4,4)) | L37: 1 | M37: 3 | N37: =IF(OR(A37="",M37="",M37=0),"",MIN(L37/M37*4,4)) | O37: 2 | P37: 4 | Q37: =IF(OR(A37="",P37="",P37=0),"",MIN(O37/P37*4,4)) | R37: =IF(A37="","",SUM(E37,H37,K37,N37,Q37)) | S37: =IF(R37="","",_xlfn.IFS(R37>=18,"S",R37>=16,"A",R37>=14,"B",R37>=11,"C",TRUE,"D"))
A38: =IF(A16="","",A16) | B38: =B16 | C38: 3 | D38: 10 | E38: =IF(OR(A38="",D38="",D38=0),"",MIN(C38/D38*4,4)) | F38: 2 | G38: 5 | H38: =IF(OR(A38="",G38="",G38=0),"",MIN(F38/G38*4,4)) | I38: 2 | J38: 6 | K38: =IF(OR(A38="",J38="",J38=0),"",MIN(I38/J38*4,4)) | L38: 1 | M38: 3 | N38: =IF(OR(A38="",M38="",M38=0),"",MIN(L38/M38*4,4)) | O38: 1 | P38: 4 | Q38: =IF(OR(A38="",P38="",P38=0),"",MIN(O38/P38*4,4)) | R38: =IF(A38="","",SUM(E38,H38,K38,N38,Q38)) | S38: =IF(R38="","",_xlfn.IFS(R38>=18,"S",R38>=16,"A",R38>=14,"B",R38>=11,"C",TRUE,"D"))
A39: =IF(A17="","",A17) | B39: =B17 | E39: =IF(OR(A39="",D39="",D39=0),"",MIN(C39/D39*4,4)) | H39: =IF(OR(A39="",G39="",G39=0),"",MIN(F39/G39*4,4)) | K39: =IF(OR(A39="",J39="",J39=0),"",MIN(I39/J39*4,4)) | N39: =IF(OR(A39="",M39="",M39=0),"",MIN(L39/M39*4,4)) | Q39: =IF(OR(A39="",P39="",P39=0),"",MIN(O39/P39*4,4)) | R39: =IF(A39="","",SUM(E39,H39,K39,N39,Q39)) | S39: =IF(R39="","",_xlfn.IFS(R39>=18,"S",R39>=16,"A",R39>=14,"B",R39>=11,"C",TRUE,"D"))
A40: =IF(A18="","",A18) | B40: =B18 | E40: =IF(OR(A40="",D40="",D40=0),"",MIN(C40/D40*4,4)) | H40: =IF(OR(A40="",G40="",G40=0),"",MIN(F40/G40*4,4)) | K40: =IF(OR(A40="",J40="",J40=0),"",MIN(I40/J40*4,4)) | N40: =IF(OR(A40="",M40="",M40=0),"",MIN(L40/M40*4,4)) | Q40: =IF(OR(A40="",P40="",P40=0),"",MIN(O40/P40*4,4)) | R40: =IF(A40="","",SUM(E40,H40,K40,N40,Q40)) | S40: =IF(R40="","",_xlfn.IFS(R40>=18,"S",R40>=16,"A",R40>=14,"B",R40>=11,"C",TRUE,"D"))
A41: =IF(A19="","",A19) | B41: =B19 | E41: =IF(OR(A41="",D41="",D41=0),"",MIN(C41/D41*4,4)) | H41: =IF(OR(A41="",G41="",G41=0),"",MIN(F41/G41*4,4)) | K41: =IF(OR(A41="",J41="",J41=0),"",MIN(I41/J41*4,4)) | N41: =IF(OR(A41="",M41="",M41=0),"",MIN(L41/M41*4,4)) | Q41: =IF(OR(A41="",P41="",P41=0),"",MIN(O41/P41*4,4)) | R41: =IF(A41="","",SUM(E41,H41,K41,N41,Q41)) | S41: =IF(R41="","",_xlfn.IFS(R41>=18,"S",R41>=16,"A",R41>=14,"B",R41>=11,"C",TRUE,"D"))
A42: =IF(A20="","",A20) | B42: =B20 | E42: =IF(OR(A42="",D42="",D42=0),"",MIN(C42/D42*4,4)) | H42: =IF(OR(A42="",G42="",G42=0),"",MIN(F42/G42*4,4)) | K42: =IF(OR(A42="",J42="",J42=0),"",MIN(I42/J42*4,4)) | N42: =IF(OR(A42="",M42="",M42=0),"",MIN(L42/M42*4,4)) | Q42: =IF(OR(A42="",P42="",P42=0),"",MIN(O42/P42*4,4)) | R42: =IF(A42="","",SUM(E42,H42,K42,N42,Q42)) | S42: =IF(R42="","",_xlfn.IFS(R42>=18,"S",R42>=16,"A",R42>=14,"B",R42>=11,"C",TRUE,"D"))
...

Sheet BD
A1: 🏠 사용안내로 이동 | E1: 📊 전사 종합요약 보기
A2: BD (Business Development) — 사업을 만든다 | ✏️ 이 시트는 잠금이 해제되어 모든 셀을 수정할 수 있습니다. 노란 셀=입력용, 회색 셀=자동계산 수식, 하늘색 셀=고정 항목이니 참고해서 편집하세요. ①결과지표 ②개별성과 ③역량평가+종합 표가 위에서 아래로 나열되어 있으며, 이름·직책은 ①표에 입력하면 ②③표에 자동으로 채워집니다(직접 고쳐도 되지만 그러면 자동연동이 끊깁니다).
A4: ① 결과지표 · 팀 공동 (50점)
A5: 이름 | B5: 직책 | C5: 실적 | D5: 목표 | E5: 달성률 | F5: 점수 (50) | G5: 등급
A6: 일지매(예시) | B6: 팀리더 | C6: =SUM(C7:C21) | D6: 50 | E6: =IF(D6=0,"",C6/D6) | F6: =IF(E6="","",MIN(E6*50,50)) | G6: =IF(F6="","",_xlfn.IFS(F6>=48,"S",F6>=45,"A",F6>=42,"B",F6>=38,"C",TRUE,"D"))
A7: 서준혁(예시) | B7: 팀원 | C7: 6 | D7: 5 | E7: =IF(OR(A7="",D7=""),"",C7/D7) | F7: =IF(A7="","",F6) | G7: =IF(A7="","",G6)
A8: 한아름(예시) | B8: 팀원 | C8: 6 | D8: 5 | E8: =IF(OR(A8="",D8=""),"",C8/D8) | F8: =IF(A8="","",F6) | G8: =IF(A8="","",G6)
A9: 오필승(예시) | B9: 팀원 | C9: 5 | D9: 5 | E9: =IF(OR(A9="",D9=""),"",C9/D9) | F9: =IF(A9="","",F6) | G9: =IF(A9="","",G6)
A10: 임하늘(예시) | B10: 팀원 | C10: 5 | D10: 5 | E10: =IF(OR(A10="",D10=""),"",C10/D10) | F10: =IF(A10="","",F6) | G10: =IF(A10="","",G6)
A11: 문가경(예시) | B11: 팀원 | C11: 4 | D11: 5 | E11: =IF(OR(A11="",D11=""),"",C11/D11) | F11: =IF(A11="","",F6) | G11: =IF(A11="","",G6)
A12: 신동율(예시) | B12: 팀원 | C12: 4 | D12: 5 | E12: =IF(OR(A12="",D12=""),"",C12/D12) | F12: =IF(A12="","",F6) | G12: =IF(A12="","",G6)
A13: 차민서(예시) | B13: 팀원 | C13: 3 | D13: 5 | E13: =IF(OR(A13="",D13=""),"",C13/D13) | F13: =IF(A13="","",F6) | G13: =IF(A13="","",G6)
A14: 구본진(예시) | B14: 팀원 | C14: 3 | D14: 5 | E14: =IF(OR(A14="",D14=""),"",C14/D14) | F14: =IF(A14="","",F6) | G14: =IF(A14="","",G6)
A15: 안유나(예시) | B15: 팀원 | C15: 3 | D15: 5 | E15: =IF(OR(A15="",D15=""),"",C15/D15) | F15: =IF(A15="","",F6) | G15: =IF(A15="","",G6)
A16: 홍서율(예시) | B16: 팀원 | C16: 2 | D16: 5 | E16: =IF(OR(A16="",D16=""),"",C16/D16) | F16: =IF(A16="","",F6) | G16: =IF(A16="","",G6)
B17: 팀원 | E17: =IF(OR(A17="",D17=""),"",C17/D17) | F17: =IF(A17="","",F6) | G17: =IF(A17="","",G6)
B18: 팀원 | E18: =IF(OR(A18="",D18=""),"",C18/D18) | F18: =IF(A18="","",F6) | G18: =IF(A18="","",G6)
B19: 팀원 | E19: =IF(OR(A19="",D19=""),"",C19/D19) | F19: =IF(A19="","",F6) | G19: =IF(A19="","",G6)
B20: 팀원 | E20: =IF(OR(A20="",D20=""),"",C20/D20) | F20: =IF(A20="","",F6) | G20: =IF(A20="","",G6)
B21: 팀원 | E21: =IF(OR(A21="",D21=""),"",C21/D21) | F21: =IF(A21="","",F6) | G21: =IF(A21="","",G6)
A22: 팀 평균 / 합계 | C22: =SUM(C7:C21) | D22: - | E22: - | F22: =F6 | G22: =G6
A24: ② 개별성과 · 정량 (과정지표Ⅰ, 20점)
A25: 이름 (①표 자동) | B25: 직책 (①표 자동) | C25: 1. (예시) 신규고객 발굴 | F25: 2. (예시) 고객 미팅·피칭 | I25: 3. (예시) 제안서 작성 | L25: 4. (예시) 계약협상 | O25: 5. (예시) 계약 후 온보딩 지원 | R25: 소계 (20) | S25: 등급
C26: 이 항목명은 예시입니다. 팀 고유 KPI로 교체하세요. 계산식 예시: 실적 ÷ 목표 × 4점 = 점수 | F26: 이 항목명은 예시입니다. 팀 고유 KPI로 교체하세요. 계산식 예시: 실적 ÷ 목표 × 4점 = 점수 | I26: 이 항목명은 예시입니다. 팀 고유 KPI로 교체하세요. 계산식 예시: 실적 ÷ 목표 × 4점 = 점수 | L26: 이 항목명은 예시입니다. 팀 고유 KPI로 교체하세요. 계산식 예시: 실적 ÷ 목표 × 4점 = 점수 | O26: 이 항목명은 예시입니다. 팀 고유 KPI로 교체하세요. 계산식 예시: 실적 ÷ 목표 × 4점 = 점수
C27: 실적 | D27: 목표 | E27: 점수 (4) | F27: 실적 | G27: 목표 | H27: 점수 (4) | I27: 실적 | J27: 목표 | K27: 점수 (4) | L27: 실적 | M27: 목표 | N27: 점수 (4) | O27: 실적 | P27: 목표 | Q27: 점수 (4)
A28: =IF(A6="","",A6) | B28: =B6 | C28: 팀리더는 개별성과(정량) 항목 해당 없음 — 팀 결과지표·역량평가 중심으로 평가
A29: =IF(A7="","",A7) | B29: =B7 | C29: 62 | D29: 50 | E29: =IF(OR(A29="",D29="",D29=0),"",MIN(C29/D29*4,4)) | F29: 37 | G29: 30 | H29: =IF(OR(A29="",G29="",G29=0),"",MIN(F29/G29*4,4)) | I29: 25 | J29: 20 | K29: =IF(OR(A29="",J29="",J29=0),"",MIN(I29/J29*4,4)) | L29: 12 | M29: 10 | N29: =IF(OR(A29="",M29="",M29=0),"",MIN(L29/M29*4,4)) | O29: 10 | P29: 8 | Q29: =IF(OR(A29="",P29="",P29=0),"",MIN(O29/P29*4,4)) | R29: =IF(A29="","",SUM(E29,H29,K29,N29,Q29)) | S29: =IF(R29="","",_xlfn.IFS(R29>=18,"S",R29>=16,"A",R29>=14,"B",R29>=11,"C",TRUE,"D"))
A30: =IF(A8="","",A8) | B30: =B8 | C30: 56 | D30: 50 | E30: =IF(OR(A30="",D30="",D30=0),"",MIN(C30/D30*4,4)) | F30: 34 | G30: 30 | H30: =IF(OR(A30="",G30="",G30=0),"",MIN(F30/G30*4,4)) | I30: 22 | J30: 20 | K30: =IF(OR(A30="",J30="",J30=0),"",MIN(I30/J30*4,4)) | L30: 11 | M30: 10 | N30: =IF(OR(A30="",M30="",M30=0),"",MIN(L30/M30*4,4)) | O30: 9 | P30: 8 | Q30: =IF(OR(A30="",P30="",P30=0),"",MIN(O30/P30*4,4)) | R30: =IF(A30="","",SUM(E30,H30,K30,N30,Q30)) | S30: =IF(R30="","",_xlfn.IFS(R30>=18,"S",R30>=16,"A",R30>=14,"B",R30>=11,"C",TRUE,"D"))
A31: =IF(A9="","",A9) | B31: =B9 | C31: 52 | D31: 50 | E31: =IF(OR(A31="",D31="",D31=0),"",MIN(C31/D31*4,4)) | F31: 31 | G31: 30 | H31: =IF(OR(A31="",G31="",G31=0),"",MIN(F31/G31*4,4)) | I31: 21 | J31: 20 | K31: =IF(OR(A31="",J31="",J31=0),"",MIN(I31/J31*4,4)) | L31: 10 | M31: 10 | N31: =IF(OR(A31="",M31="",M31=0),"",MIN(L31/M31*4,4)) | O31: 8 | P31: 8 | Q31: =IF(OR(A31="",P31="",P31=0),"",MIN(O31/P31*4,4)) | R31: =IF(A31="","",SUM(E31,H31,K31,N31,Q31)) | S31: =IF(R31="","",_xlfn.IFS(R31>=18,"S",R31>=16,"A",R31>=14,"B",R31>=11,"C",TRUE,"D"))
A32: =IF(A10="","",A10) | B32: =B10 | C32: 48 | D32: 50 | E32: =IF(OR(A32="",D32="",D32=0),"",MIN(C32/D32*4,4)) | F32: 29 | G32: 30 | H32: =IF(OR(A32="",G32="",G32=0),"",MIN(F32/G32*4,4)) | I32: 19 | J32: 20 | K32: =IF(OR(A32="",J32="",J32=0),"",MIN(I32/J32*4,4)) | L32: 10 | M32: 10 | N32: =IF(OR(A32="",M32="",M32=0),"",MIN(L32/M32*4,4)) | O32: 8 | P32: 8 | Q32: =IF(OR(A32="",P32="",P32=0),"",MIN(O32/P32*4,4)) | R32: =IF(A32="","",SUM(E32,H32,K32,N32,Q32)) | S32: =IF(R32="","",_xlfn.IFS(R32>=18,"S",R32>=16,"A",R32>=14,"B",R32>=11,"C",TRUE,"D"))
A33: =IF(A11="","",A11) | B33: =B11 | C33: 44 | D33: 50 | E33: =IF(OR(A33="",D33="",D33=0),"",MIN(C33/D33*4,4)) | F33: 26 | G33: 30 | H33: =IF(OR(A33="",G33="",G33=0),"",MIN(F33/G33*4,4)) | I33: 17 | J33: 20 | K33: =IF(OR(A33="",J33="",J33=0),"",MIN(I33/J33*4,4)) | L33: 9 | M33: 10 | N33: =IF(OR(A33="",M33="",M33=0),"",MIN(L33/M33*4,4)) | O33: 7 | P33: 8 | Q33: =IF(OR(A33="",P33="",P33=0),"",MIN(O33/P33*4,4)) | R33: =IF(A33="","",SUM(E33,H33,K33,N33,Q33)) | S33: =IF(R33="","",_xlfn.IFS(R33>=18,"S",R33>=16,"A",R33>=14,"B",R33>=11,"C",TRUE,"D"))
A34: =IF(A12="","",A12) | B34: =B12 | C34: 39 | D34: 50 | E34: =IF(OR(A34="",D34="",D34=0),"",MIN(C34/D34*4,4)) | F34: 24 | G34: 30 | H34: =IF(OR(A34="",G34="",G34=0),"",MIN(F34/G34*4,4)) | I34: 16 | J34: 20 | K34: =IF(OR(A34="",J34="",J34=0),"",MIN(I34/J34*4,4)) | L34: 8 | M34: 10 | N34: =IF(OR(A34="",M34="",M34=0),"",MIN(L34/M34*4,4)) | O34: 6 | P34: 8 | Q34: =IF(OR(A34="",P34="",P34=0),"",MIN(O34/P34*4,4)) | R34: =IF(A34="","",SUM(E34,H34,K34,N34,Q34)) | S34: =IF(R34="","",_xlfn.IFS(R34>=18,"S",R34>=16,"A",R34>=14,"B",R34>=11,"C",TRUE,"D"))
A35: =IF(A13="","",A13) | B35: =B13 | C35: 35 | D35: 50 | E35: =IF(OR(A35="",D35="",D35=0),"",MIN(C35/D35*4,4)) | F35: 21 | G35: 30 | H35: =IF(OR(A35="",G35="",G35=0),"",MIN(F35/G35*4,4)) | I35: 14 | J35: 20 | K35: =IF(OR(A35="",J35="",J35=0),"",MIN(I35/J35*4,4)) | L35: 7 | M35: 10 | N35: =IF(OR(A35="",M35="",M35=0),"",MIN(L35/M35*4,4)) | O35: 6 | P35: 8 | Q35: =IF(OR(A35="",P35="",P35=0),"",MIN(O35/P35*4,4)) | R35: =IF(A35="","",SUM(E35,H35,K35,N35,Q35)) | S35: =IF(R35="","",_xlfn.IFS(R35>=18,"S",R35>=16,"A",R35>=14,"B",R35>=11,"C",TRUE,"D"))
A36: =IF(A14="","",A14) | B36: =B14 | C36: 31 | D36: 50 | E36: =IF(OR(A36="",D36="",D36=0),"",MIN(C36/D36*4,4)) | F36: 18 | G36: 30 | H36: =IF(OR(A36="",G36="",G36=0),"",MIN(F36/G36*4,4)) | I36: 12 | J36: 20 | K36: =IF(OR(A36="",J36="",J36=0),"",MIN(I36/J36*4,4)) | L36: 6 | M36: 10 | N36: =IF(OR(A36="",M36="",M36=0),"",MIN(L36/M36*4,4)) | O36: 5 | P36: 8 | Q36: =IF(OR(A36="",P36="",P36=0),"",MIN(O36/P36*4,4)) | R36: =IF(A36="","",SUM(E36,H36,K36,N36,Q36)) | S36: =IF(R36="","",_xlfn.IFS(R36>=18,"S",R36>=16,"A",R36>=14,"B",R36>=11,"C",TRUE,"D"))
A37: =IF(A15="","",A15) | B37: =B15 | C37: 25 | D37: 50 | E37: =IF(OR(A37="",D37="",D37=0),"",MIN(C37/D37*4,4)) | F37: 15 | G37: 30 | H37: =IF(OR(A37="",G37="",G37=0),"",MIN(F37/G37*4,4)) | I37: 10 | J37: 20 | K37: =IF(OR(A37="",J37="",J37=0),"",MIN(I37/J37*4,4)) | L37: 5 | M37: 10 | N37: =IF(OR(A37="",M37="",M37=0),"",MIN(L37/M37*4,4)) | O37: 4 | P37: 8 | Q37: =IF(OR(A37="",P37="",P37=0),"",MIN(O37/P37*4,4)) | R37: =IF(A37="","",SUM(E37,H37,K37,N37,Q37)) | S37: =IF(R37="","",_xlfn.IFS(R37>=18,"S",R37>=16,"A",R37>=14,"B",R37>=11,"C",TRUE,"D"))
A38: =IF(A16="","",A16) | B38: =B16 | C38: 20 | D38: 50 | E38: =IF(OR(A38="",D38="",D38=0),"",MIN(C38/D38*4,4)) | F38: 12 | G38: 30 | H38: =IF(OR(A38="",G38="",G38=0),"",MIN(F38/G38*4,4)) | I38: 8 | J38: 20 | K38: =IF(OR(A38="",J38="",J38=0),"",MIN(I38/J38*4,4)) | L38: 4 | M38: 10 | N38: =IF(OR(A38="",M38="",M38=0),"",MIN(L38/M38*4,4)) | O38: 3 | P38: 8 | Q38: =IF(OR(A38="",P38="",P38=0),"",MIN(O38/P38*4,4)) | R38: =IF(A38="","",SUM(E38,H38,K38,N38,Q38)) | S38: =IF(R38="","",_xlfn.IFS(R38>=18,"S",R38>=16,"A",R38>=14,"B",R38>=11,"C",TRUE,"D"))
A39: =IF(A17="","",A17) | B39: =B17 | E39: =IF(OR(A39="",D39="",D39=0),"",MIN(C39/D39*4,4)) | H39: =IF(OR(A39="",G39="",G39=0),"",MIN(F39/G39*4,4)) | K39: =IF(OR(A39="",J39="",J39=0),"",MIN(I39/J39*4,4)) | N39: =IF(OR(A39="",M39="",M39=0),"",MIN(L39/M39*4,4)) | Q39: =IF(OR(A39="",P39="",P39=0),"",MIN(O39/P39*4,4)) | R39: =IF(A39="","",SUM(E39,H39,K39,N39,Q39)) | S39: =IF(R39="","",_xlfn.IFS(R39>=18,"S",R39>=16,"A",R39>=14,"B",R39>=11,"C",TRUE,"D"))
A40: =IF(A18="","",A18) | B40: =B18 | E40: =IF(OR(A40="",D40="",D40=0),"",MIN(C40/D40*4,4)) | H40: =IF(OR(A40="",G40="",G40=0),"",MIN(F40/G40*4,4)) | K40: =IF(OR(A40="",J40="",J40=0),"",MIN(I40/J40*4,4)) | N40: =IF(OR(A40="",M40="",M40=0),"",MIN(L40/M40*4,4)) | Q40: =IF(OR(A40="",P40="",P40=0),"",MIN(O40/P40*4,4)) | R40: =IF(A40="","",SUM(E40,H40,K40,N40,Q40)) | S40: =IF(R40="","",_xlfn.IFS(R40>=18,"S",R40>=16,"A",R40>=14,"B",R40>=11,"C",TRUE,"D"))
A41: =IF(A19="","",A19) | B41: =B19 | E41: =IF(OR(A41="",D41="",D41=0),"",MIN(C41/D41*4,4)) | H41: =IF(OR(A41="",G41="",G41=0),"",MIN(F41/G41*4,4)) | K41: =IF(OR(A41="",J41="",J41=0),"",MIN(I41/J41*4,4)) | N41: =IF(OR(A41="",M41="",M41=0),"",MIN(L41/M41*4,4)) | Q41: =IF(OR(A41="",P41="",P41=0),"",MIN(O41/P41*4,4)) | R41: =IF(A41="","",SUM(E41,H41,K41,N41,Q41)) | S41: =IF(R41="","",_xlfn.IFS(R41>=18,"S",R41>=16,"A",R41>=14,"B",R41>=11,"C",TRUE,"D"))
A42: =IF(A20="","",A20) | B42: =B20 | E42: =IF(OR(A42="",D42="",D42=0),"",MIN(C42/D42*4,4)) | H42: =IF(OR(A42="",G42="",G42=0),"",MIN(F42/G42*4,4)) | K42: =IF(OR(A42="",J42="",J42=0),"",MIN(I42/J42*4,4)) | N42: =IF(OR(A42="",M42="",M42=0),"",MIN(L42/M42*4,4)) | Q42: =IF(OR(A42="",P42="",P42=0),"",MIN(O42/P42*4,4)) | R42: =IF(A42="","",SUM(E42,H42,K42,N42,Q42)) | S42: =IF(R42="","",_xlfn.IFS(R42>=18,"S",R42>=16,"A",R42>=14,"B",R42>=11,"C",TRUE,"D"))
...

Sheet PB
A1: 🏠 사용안내로 이동 | E1: 📊 전사 종합요약 보기
A2: PB (Product Build) — 제품을 구현한다 | ✏️ 이 시트는 잠금이 해제되어 모든 셀을 수정할 수 있습니다. 노란 셀=입력용, 회색 셀=자동계산 수식, 하늘색 셀=고정 항목이니 참고해서 편집하세요. ①결과지표 ②개별성과 ③역량평가+종합 표가 위에서 아래로 나열되어 있으며, 이름·직책은 ①표에 입력하면 ②③표에 자동으로 채워집니다(직접 고쳐도 되지만 그러면 자동연동이 끊깁니다).
A4: ① 결과지표 · 팀 공동 (50점)
A5: 이름 | B5: 직책 | C5: 실적 | D5: 목표 | E5: 달성률 | F5: 점수 (50) | G5: 등급
A6: 장금이(예시) | B6: 팀리더 | C6: =SUM(C7:C21) | D6: 12 | E6: =IF(D6=0,"",C6/D6) | F6: =IF(E6="","",MIN(E6*50,50)) | G6: =IF(F6="","",_xlfn.IFS(F6>=48,"S",F6>=45,"A",F6>=42,"B",F6>=38,"C",TRUE,"D"))
A7: 임도경(예시) | B7: 팀원 | C7: 5 | D7: 5 | E7: =IF(OR(A7="",D7=""),"",C7/D7) | F7: =IF(A7="","",F6) | G7: =IF(A7="","",G6)
A8: 신유나(예시) | B8: 팀원 | C8: 4 | D8: 5 | E8: =IF(OR(A8="",D8=""),"",C8/D8) | F8: =IF(A8="","",F6) | G8: =IF(A8="","",G6)
A9: 곽태호(예시) | B9: 팀원 | C9: 4 | D9: 5 | E9: =IF(OR(A9="",D9=""),"",C9/D9) | F9: =IF(A9="","",F6) | G9: =IF(A9="","",G6)
A10: 백마리(예시) | B10: 팀원 | C10: 4 | D10: 5 | E10: =IF(OR(A10="",D10=""),"",C10/D10) | F10: =IF(A10="","",F6) | G10: =IF(A10="","",G6)
A11: 노준서(예시) | B11: 팀원 | C11: 3 | D11: 5 | E11: =IF(OR(A11="",D11=""),"",C11/D11) | F11: =IF(A11="","",F6) | G11: =IF(A11="","",G6)
A12: 정하람(예시) | B12: 팀원 | C12: 3 | D12: 5 | E12: =IF(OR(A12="",D12=""),"",C12/D12) | F12: =IF(A12="","",F6) | G12: =IF(A12="","",G6)
A13: 이시율(예시) | B13: 팀원 | C13: 3 | D13: 5 | E13: =IF(OR(A13="",D13=""),"",C13/D13) | F13: =IF(A13="","",F6) | G13: =IF(A13="","",G6)
A14: 박지완(예시) | B14: 팀원 | C14: 2 | D14: 5 | E14: =IF(OR(A14="",D14=""),"",C14/D14) | F14: =IF(A14="","",F6) | G14: =IF(A14="","",G6)
A15: 최다인(예시) | B15: 팀원 | C15: 2 | D15: 5 | E15: =IF(OR(A15="",D15=""),"",C15/D15) | F15: =IF(A15="","",F6) | G15: =IF(A15="","",G6)
A16: 김리안(예시) | B16: 팀원 | C16: 1 | D16: 5 | E16: =IF(OR(A16="",D16=""),"",C16/D16) | F16: =IF(A16="","",F6) | G16: =IF(A16="","",G6)
B17: 팀원 | E17: =IF(OR(A17="",D17=""),"",C17/D17) | F17: =IF(A17="","",F6) | G17: =IF(A17="","",G6)
B18: 팀원 | E18: =IF(OR(A18="",D18=""),"",C18/D18) | F18: =IF(A18="","",F6) | G18: =IF(A18="","",G6)
B19: 팀원 | E19: =IF(OR(A19="",D19=""),"",C19/D19) | F19: =IF(A19="","",F6) | G19: =IF(A19="","",G6)
B20: 팀원 | E20: =IF(OR(A20="",D20=""),"",C20/D20) | F20: =IF(A20="","",F6) | G20: =IF(A20="","",G6)
B21: 팀원 | E21: =IF(OR(A21="",D21=""),"",C21/D21) | F21: =IF(A21="","",F6) | G21: =IF(A21="","",G6)
A22: 팀 평균 / 합계 | C22: =SUM(C7:C21) | D22: - | E22: - | F22: =F6 | G22: =G6
A24: ② 개별성과 · 정량 (과정지표Ⅰ, 20점)
A25: 이름 (①표 자동) | B25: 직책 (①표 자동) | C25: 1. (예시) 스프린트 기능개발 | F25: 2. (예시) PR 코드리뷰 | I25: 3. (예시) 고객 데모 지원 | L25: 4. (예시) 컨설팅 검증 지원 | O25: 5. (예시) 배포·릴리즈 관리 | R25: 소계 (20) | S25: 등급
C26: 이 항목명은 예시입니다. 팀 고유 KPI로 교체하세요. 계산식 예시: 실적 ÷ 목표 × 4점 = 점수 | F26: 이 항목명은 예시입니다. 팀 고유 KPI로 교체하세요. 계산식 예시: 실적 ÷ 목표 × 4점 = 점수 | I26: 이 항목명은 예시입니다. 팀 고유 KPI로 교체하세요. 계산식 예시: 실적 ÷ 목표 × 4점 = 점수 | L26: 이 항목명은 예시입니다. 팀 고유 KPI로 교체하세요. 계산식 예시: 실적 ÷ 목표 × 4점 = 점수 | O26: 이 항목명은 예시입니다. 팀 고유 KPI로 교체하세요. 계산식 예시: 실적 ÷ 목표 × 4점 = 점수
C27: 실적 | D27: 목표 | E27: 점수 (4) | F27: 실적 | G27: 목표 | H27: 점수 (4) | I27: 실적 | J27: 목표 | K27: 점수 (4) | L27: 실적 | M27: 목표 | N27: 점수 (4) | O27: 실적 | P27: 목표 | Q27: 점수 (4)
A28: =IF(A6="","",A6) | B28: =B6 | C28: 팀리더는 개별성과(정량) 항목 해당 없음 — 팀 결과지표·역량평가 중심으로 평가
A29: =IF(A7="","",A7) | B29: =B7 | C29: 7 | D29: 8 | E29: =IF(OR(A29="",D29="",D29=0),"",MIN(C29/D29*4,4)) | F29: 14 | G29: 15 | H29: =IF(OR(A29="",G29="",G29=0),"",MIN(F29/G29*4,4)) | I29: 5 | J29: 5 | K29: =IF(OR(A29="",J29="",J29=0),"",MIN(I29/J29*4,4)) | L29: 4 | M29: 4 | N29: =IF(OR(A29="",M29="",M29=0),"",MIN(L29/M29*4,4)) | O29: 6 | P29: 6 | Q29: =IF(OR(A29="",P29="",P29=0),"",MIN(O29/P29*4,4)) | R29: =IF(A29="","",SUM(E29,H29,K29,N29,Q29)) | S29: =IF(R29="","",_xlfn.IFS(R29>=18,"S",R29>=16,"A",R29>=14,"B",R29>=11,"C",TRUE,"D"))
A30: =IF(A8="","",A8) | B30: =B8 | C30: 7 | D30: 8 | E30: =IF(OR(A30="",D30="",D30=0),"",MIN(C30/D30*4,4)) | F30: 13 | G30: 15 | H30: =IF(OR(A30="",G30="",G30=0),"",MIN(F30/G30*4,4)) | I30: 4 | J30: 5 | K30: =IF(OR(A30="",J30="",J30=0),"",MIN(I30/J30*4,4)) | L30: 3 | M30: 4 | N30: =IF(OR(A30="",M30="",M30=0),"",MIN(L30/M30*4,4)) | O30: 5 | P30: 6 | Q30: =IF(OR(A30="",P30="",P30=0),"",MIN(O30/P30*4,4)) | R30: =IF(A30="","",SUM(E30,H30,K30,N30,Q30)) | S30: =IF(R30="","",_xlfn.IFS(R30>=18,"S",R30>=16,"A",R30>=14,"B",R30>=11,"C",TRUE,"D"))
A31: =IF(A9="","",A9) | B31: =B9 | C31: 6 | D31: 8 | E31: =IF(OR(A31="",D31="",D31=0),"",MIN(C31/D31*4,4)) | F31: 12 | G31: 15 | H31: =IF(OR(A31="",G31="",G31=0),"",MIN(F31/G31*4,4)) | I31: 4 | J31: 5 | K31: =IF(OR(A31="",J31="",J31=0),"",MIN(I31/J31*4,4)) | L31: 3 | M31: 4 | N31: =IF(OR(A31="",M31="",M31=0),"",MIN(L31/M31*4,4)) | O31: 5 | P31: 6 | Q31: =IF(OR(A31="",P31="",P31=0),"",MIN(O31/P31*4,4)) | R31: =IF(A31="","",SUM(E31,H31,K31,N31,Q31)) | S31: =IF(R31="","",_xlfn.IFS(R31>=18,"S",R31>=16,"A",R31>=14,"B",R31>=11,"C",TRUE,"D"))
A32: =IF(A10="","",A10) | B32: =B10 | C32: 6 | D32: 8 | E32: =IF(OR(A32="",D32="",D32=0),"",MIN(C32/D32*4,4)) | F32: 11 | G32: 15 | H32: =IF(OR(A32="",G32="",G32=0),"",MIN(F32/G32*4,4)) | I32: 4 | J32: 5 | K32: =IF(OR(A32="",J32="",J32=0),"",MIN(I32/J32*4,4)) | L32: 3 | M32: 4 | N32: =IF(OR(A32="",M32="",M32=0),"",MIN(L32/M32*4,4)) | O32: 4 | P32: 6 | Q32: =IF(OR(A32="",P32="",P32=0),"",MIN(O32/P32*4,4)) | R32: =IF(A32="","",SUM(E32,H32,K32,N32,Q32)) | S32: =IF(R32="","",_xlfn.IFS(R32>=18,"S",R32>=16,"A",R32>=14,"B",R32>=11,"C",TRUE,"D"))
A33: =IF(A11="","",A11) | B33: =B11 | C33: 5 | D33: 8 | E33: =IF(OR(A33="",D33="",D33=0),"",MIN(C33/D33*4,4)) | F33: 10 | G33: 15 | H33: =IF(OR(A33="",G33="",G33=0),"",MIN(F33/G33*4,4)) | I33: 3 | J33: 5 | K33: =IF(OR(A33="",J33="",J33=0),"",MIN(I33/J33*4,4)) | L33: 3 | M33: 4 | N33: =IF(OR(A33="",M33="",M33=0),"",MIN(L33/M33*4,4)) | O33: 4 | P33: 6 | Q33: =IF(OR(A33="",P33="",P33=0),"",MIN(O33/P33*4,4)) | R33: =IF(A33="","",SUM(E33,H33,K33,N33,Q33)) | S33: =IF(R33="","",_xlfn.IFS(R33>=18,"S",R33>=16,"A",R33>=14,"B",R33>=11,"C",TRUE,"D"))
A34: =IF(A12="","",A12) | B34: =B12 | C34: 5 | D34: 8 | E34: =IF(OR(A34="",D34="",D34=0),"",MIN(C34/D34*4,4)) | F34: 9 | G34: 15 | H34: =IF(OR(A34="",G34="",G34=0),"",MIN(F34/G34*4,4)) | I34: 3 | J34: 5 | K34: =IF(OR(A34="",J34="",J34=0),"",MIN(I34/J34*4,4)) | L34: 2 | M34: 4 | N34: =IF(OR(A34="",M34="",M34=0),"",MIN(L34/M34*4,4)) | O34: 4 | P34: 6 | Q34: =IF(OR(A34="",P34="",P34=0),"",MIN(O34/P34*4,4)) | R34: =IF(A34="","",SUM(E34,H34,K34,N34,Q34)) | S34: =IF(R34="","",_xlfn.IFS(R34>=18,"S",R34>=16,"A",R34>=14,"B",R34>=11,"C",TRUE,"D"))
A35: =IF(A13="","",A13) | B35: =B13 | C35: 4 | D35: 8 | E35: =IF(OR(A35="",D35="",D35=0),"",MIN(C35/D35*4,4)) | F35: 8 | G35: 15 | H35: =IF(OR(A35="",G35="",G35=0),"",MIN(F35/G35*4,4)) | I35: 3 | J35: 5 | K35: =IF(OR(A35="",J35="",J35=0),"",MIN(I35/J35*4,4)) | L35: 2 | M35: 4 | N35: =IF(OR(A35="",M35="",M35=0),"",MIN(L35/M35*4,4)) | O35: 3 | P35: 6 | Q35: =IF(OR(A35="",P35="",P35=0),"",MIN(O35/P35*4,4)) | R35: =IF(A35="","",SUM(E35,H35,K35,N35,Q35)) | S35: =IF(R35="","",_xlfn.IFS(R35>=18,"S",R35>=16,"A",R35>=14,"B",R35>=11,"C",TRUE,"D"))
A36: =IF(A14="","",A14) | B36: =B14 | C36: 4 | D36: 8 | E36: =IF(OR(A36="",D36="",D36=0),"",MIN(C36/D36*4,4)) | F36: 7 | G36: 15 | H36: =IF(OR(A36="",G36="",G36=0),"",MIN(F36/G36*4,4)) | I36: 2 | J36: 5 | K36: =IF(OR(A36="",J36="",J36=0),"",MIN(I36/J36*4,4)) | L36: 2 | M36: 4 | N36: =IF(OR(A36="",M36="",M36=0),"",MIN(L36/M36*4,4)) | O36: 3 | P36: 6 | Q36: =IF(OR(A36="",P36="",P36=0),"",MIN(O36/P36*4,4)) | R36: =IF(A36="","",SUM(E36,H36,K36,N36,Q36)) | S36: =IF(R36="","",_xlfn.IFS(R36>=18,"S",R36>=16,"A",R36>=14,"B",R36>=11,"C",TRUE,"D"))
A37: =IF(A15="","",A15) | B37: =B15 | C37: 3 | D37: 8 | E37: =IF(OR(A37="",D37="",D37=0),"",MIN(C37/D37*4,4)) | F37: 6 | G37: 15 | H37: =IF(OR(A37="",G37="",G37=0),"",MIN(F37/G37*4,4)) | I37: 2 | J37: 5 | K37: =IF(OR(A37="",J37="",J37=0),"",MIN(I37/J37*4,4)) | L37: 2 | M37: 4 | N37: =IF(OR(A37="",M37="",M37=0),"",MIN(L37/M37*4,4)) | O37: 2 | P37: 6 | Q37: =IF(OR(A37="",P37="",P37=0),"",MIN(O37/P37*4,4)) | R37: =IF(A37="","",SUM(E37,H37,K37,N37,Q37)) | S37: =IF(R37="","",_xlfn.IFS(R37>=18,"S",R37>=16,"A",R37>=14,"B",R37>=11,"C",TRUE,"D"))
A38: =IF(A16="","",A16) | B38: =B16 | C38: 2 | D38: 8 | E38: =IF(OR(A38="",D38="",D38=0),"",MIN(C38/D38*4,4)) | F38: 4 | G38: 15 | H38: =IF(OR(A38="",G38="",G38=0),"",MIN(F38/G38*4,4)) | I38: 1 | J38: 5 | K38: =IF(OR(A38="",J38="",J38=0),"",MIN(I38/J38*4,4)) | L38: 1 | M38: 4 | N38: =IF(OR(A38="",M38="",M38=0),"",MIN(L38/M38*4,4)) | O38: 2 | P38: 6 | Q38: =IF(OR(A38="",P38="",P38=0),"",MIN(O38/P38*4,4)) | R38: =IF(A38="","",SUM(E38,H38,K38,N38,Q38)) | S38: =IF(R38="","",_xlfn.IFS(R38>=18,"S",R38>=16,"A",R38>=14,"B",R38>=11,"C",TRUE,"D"))
A39: =IF(A17="","",A17) | B39: =B17 | E39: =IF(OR(A39="",D39="",D39=0),"",MIN(C39/D39*4,4)) | H39: =IF(OR(A39="",G39="",G39=0),"",MIN(F39/G39*4,4)) | K39: =IF(OR(A39="",J39="",J39=0),"",MIN(I39/J39*4,4)) | N39: =IF(OR(A39="",M39="",M39=0),"",MIN(L39/M39*4,4)) | Q39: =IF(OR(A39="",P39="",P39=0),"",MIN(O39/P39*4,4)) | R39: =IF(A39="","",SUM(E39,H39,K39,N39,Q39)) | S39: =IF(R39="","",_xlfn.IFS(R39>=18,"S",R39>=16,"A",R39>=14,"B",R39>=11,"C",TRUE,"D"))
A40: =IF(A18="","",A18) | B40: =B18 | E40: =IF(OR(A40="",D40="",D40=0),"",MIN(C40/D40*4,4)) | H40: =IF(OR(A40="",G40="",G40=0),"",MIN(F40/G40*4,4)) | K40: =IF(OR(A40="",J40="",J40=0),"",MIN(I40/J40*4,4)) | N40: =IF(OR(A40="",M40="",M40=0),"",MIN(L40/M40*4,4)) | Q40: =IF(OR(A40="",P40="",P40=0),"",MIN(O40/P40*4,4)) | R40: =IF(A40="","",SUM(E40,H40,K40,N40,Q40)) | S40: =IF(R40="","",_xlfn.IFS(R40>=18,"S",R40>=16,"A",R40>=14,"B",R40>=11,"C",TRUE,"D"))
A41: =IF(A19="","",A19) | B41: =B19 | E41: =IF(OR(A41="",D41="",D41=0),"",MIN(C41/D41*4,4)) | H41: =IF(OR(A41="",G41="",G41=0),"",MIN(F41/G41*4,4)) | K41: =IF(OR(A41="",J41="",J41=0),"",MIN(I41/J41*4,4)) | N41: =IF(OR(A41="",M41="",M41=0),"",MIN(L41/M41*4,4)) | Q41: =IF(OR(A41="",P41="",P41=0),"",MIN(O41/P41*4,4)) | R41: =IF(A41="","",SUM(E41,H41,K41,N41,Q41)) | S41: =IF(R41="","",_xlfn.IFS(R41>=18,"S",R41>=16,"A",R41>=14,"B",R41>=11,"C",TRUE,"D"))
A42: =IF(A20="","",A20) | B42: =B20 | E42: =IF(OR(A42="",D42="",D42=0),"",MIN(C42/D42*4,4)) | H42: =IF(OR(A42="",G42="",G42=0),"",MIN(F42/G42*4,4)) | K42: =IF(OR(A42="",J42="",J42=0),"",MIN(I42/J42*4,4)) | N42: =IF(OR(A42="",M42="",M42=0),"",MIN(L42/M42*4,4)) | Q42: =IF(OR(A42="",P42="",P42=0),"",MIN(O42/P42*4,4)) | R42: =IF(A42="","",SUM(E42,H42,K42,N42,Q42)) | S42: =IF(R42="","",_xlfn.IFS(R42>=18,"S",R42>=16,"A",R42>=14,"B",R42>=11,"C",TRUE,"D"))
...

Sheet BM
A1: 🏠 사용안내로 이동 | E1: 📊 전사 종합요약 보기
A2: BM (Business Management) — 사업을 관리·지원한다 | ✏️ 이 시트는 잠금이 해제되어 모든 셀을 수정할 수 있습니다. 노란 셀=입력용, 회색 셀=자동계산 수식, 하늘색 셀=고정 항목이니 참고해서 편집하세요. ①결과지표 ②개별성과 ③역량평가+종합 표가 위에서 아래로 나열되어 있으며, 이름·직책은 ①표에 입력하면 ②③표에 자동으로 채워집니다(직접 고쳐도 되지만 그러면 자동연동이 끊깁니다).
A4: ① 결과지표 · 팀 공동 (50점)
A5: 이름 | B5: 직책 | C5: 실적 | D5: 목표 | E5: 달성률 | F5: 점수 (50) | G5: 등급
A6: 변사또(예시) | B6: 팀리더 | C6: =SUM(C7:C21) | D6: 20 | E6: =IF(D6=0,"",C6/D6) | F6: =IF(E6="","",MIN(E6*50,50)) | G6: =IF(F6="","",_xlfn.IFS(F6>=48,"S",F6>=45,"A",F6>=42,"B",F6>=38,"C",TRUE,"D"))
A7: 육예린(예시) | B7: 팀원 | C7: 6 | D7: 5 | E7: =IF(OR(A7="",D7=""),"",C7/D7) | F7: =IF(A7="","",F6) | G7: =IF(A7="","",G6)
A8: 곽태산(예시) | B8: 팀원 | C8: 5 | D8: 5 | E8: =IF(OR(A8="",D8=""),"",C8/D8) | F8: =IF(A8="","",F6) | G8: =IF(A8="","",G6)
A9: 편지영(예시) | B9: 팀원 | C9: 5 | D9: 5 | E9: =IF(OR(A9="",D9=""),"",C9/D9) | F9: =IF(A9="","",F6) | G9: =IF(A9="","",G6)
A10: 탁수진(예시) | B10: 팀원 | C10: 4 | D10: 5 | E10: =IF(OR(A10="",D10=""),"",C10/D10) | F10: =IF(A10="","",F6) | G10: =IF(A10="","",G6)
A11: 나윤서(예시) | B11: 팀원 | C11: 4 | D11: 5 | E11: =IF(OR(A11="",D11=""),"",C11/D11) | F11: =IF(A11="","",F6) | G11: =IF(A11="","",G6)
A12: 마도현(예시) | B12: 팀원 | C12: 4 | D12: 5 | E12: =IF(OR(A12="",D12=""),"",C12/D12) | F12: =IF(A12="","",F6) | G12: =IF(A12="","",G6)
A13: 라시은(예시) | B13: 팀원 | C13: 3 | D13: 5 | E13: =IF(OR(A13="",D13=""),"",C13/D13) | F13: =IF(A13="","",F6) | G13: =IF(A13="","",G6)
A14: 표승민(예시) | B14: 팀원 | C14: 3 | D14: 5 | E14: =IF(OR(A14="",D14=""),"",C14/D14) | F14: =IF(A14="","",F6) | G14: =IF(A14="","",G6)
A15: 우지안(예시) | B15: 팀원 | C15: 2 | D15: 5 | E15: =IF(OR(A15="",D15=""),"",C15/D15) | F15: =IF(A15="","",F6) | G15: =IF(A15="","",G6)
A16: 함서율(예시) | B16: 팀원 | C16: 2 | D16: 5 | E16: =IF(OR(A16="",D16=""),"",C16/D16) | F16: =IF(A16="","",F6) | G16: =IF(A16="","",G6)
B17: 팀원 | E17: =IF(OR(A17="",D17=""),"",C17/D17) | F17: =IF(A17="","",F6) | G17: =IF(A17="","",G6)
B18: 팀원 | E18: =IF(OR(A18="",D18=""),"",C18/D18) | F18: =IF(A18="","",F6) | G18: =IF(A18="","",G6)
B19: 팀원 | E19: =IF(OR(A19="",D19=""),"",C19/D19) | F19: =IF(A19="","",F6) | G19: =IF(A19="","",G6)
B20: 팀원 | E20: =IF(OR(A20="",D20=""),"",C20/D20) | F20: =IF(A20="","",F6) | G20: =IF(A20="","",G6)
B21: 팀원 | E21: =IF(OR(A21="",D21=""),"",C21/D21) | F21: =IF(A21="","",F6) | G21: =IF(A21="","",G6)
A22: 팀 평균 / 합계 | C22: =SUM(C7:C21) | D22: - | E22: - | F22: =F6 | G22: =G6
A24: ② 개별성과 · 정량 (과정지표Ⅰ, 20점)
A25: 이름 (①표 자동) | B25: 직책 (①표 자동) | C25: 1. (예시) 법무검토 지원 | F25: 2. (예시) 회계결산 처리 | I25: 3. (예시) 채용전형 지원 | L25: 4. (예시) 사내 행정지원 | O25: 5. (예시) 경영 리포트 작성 | R25: 소계 (20) | S25: 등급
C26: 이 항목명은 예시입니다. 팀 고유 KPI로 교체하세요. 계산식 예시: 실적 ÷ 목표 × 4점 = 점수 | F26: 이 항목명은 예시입니다. 팀 고유 KPI로 교체하세요. 계산식 예시: 실적 ÷ 목표 × 4점 = 점수 | I26: 이 항목명은 예시입니다. 팀 고유 KPI로 교체하세요. 계산식 예시: 실적 ÷ 목표 × 4점 = 점수 | L26: 이 항목명은 예시입니다. 팀 고유 KPI로 교체하세요. 계산식 예시: 실적 ÷ 목표 × 4점 = 점수 | O26: 이 항목명은 예시입니다. 팀 고유 KPI로 교체하세요. 계산식 예시: 실적 ÷ 목표 × 4점 = 점수
C27: 실적 | D27: 목표 | E27: 점수 (4) | F27: 실적 | G27: 목표 | H27: 점수 (4) | I27: 실적 | J27: 목표 | K27: 점수 (4) | L27: 실적 | M27: 목표 | N27: 점수 (4) | O27: 실적 | P27: 목표 | Q27: 점수 (4)
A28: =IF(A6="","",A6) | B28: =B6 | C28: 팀리더는 개별성과(정량) 항목 해당 없음 — 팀 결과지표·역량평가 중심으로 평가
A29: =IF(A7="","",A7) | B29: =B7 | C29: 9 | D29: 8 | E29: =IF(OR(A29="",D29="",D29=0),"",MIN(C29/D29*4,4)) | F29: 12 | G29: 10 | H29: =IF(OR(A29="",G29="",G29=0),"",MIN(F29/G29*4,4)) | I29: 7 | J29: 6 | K29: =IF(OR(A29="",J29="",J29=0),"",MIN(I29/J29*4,4)) | L29: 12 | M29: 10 | N29: =IF(OR(A29="",M29="",M29=0),"",MIN(L29/M29*4,4)) | O29: 5 | P29: 4 | Q29: =IF(OR(A29="",P29="",P29=0),"",MIN(O29/P29*4,4)) | R29: =IF(A29="","",SUM(E29,H29,K29,N29,Q29)) | S29: =IF(R29="","",_xlfn.IFS(R29>=18,"S",R29>=16,"A",R29>=14,"B",R29>=11,"C",TRUE,"D"))
A30: =IF(A8="","",A8) | B30: =B8 | C30: 8 | D30: 8 | E30: =IF(OR(A30="",D30="",D30=0),"",MIN(C30/D30*4,4)) | F30: 10 | G30: 10 | H30: =IF(OR(A30="",G30="",G30=0),"",MIN(F30/G30*4,4)) | I30: 6 | J30: 6 | K30: =IF(OR(A30="",J30="",J30=0),"",MIN(I30/J30*4,4)) | L30: 10 | M30: 10 | N30: =IF(OR(A30="",M30="",M30=0),"",MIN(L30/M30*4,4)) | O30: 4 | P30: 4 | Q30: =IF(OR(A30="",P30="",P30=0),"",MIN(O30/P30*4,4)) | R30: =IF(A30="","",SUM(E30,H30,K30,N30,Q30)) | S30: =IF(R30="","",_xlfn.IFS(R30>=18,"S",R30>=16,"A",R30>=14,"B",R30>=11,"C",TRUE,"D"))
A31: =IF(A9="","",A9) | B31: =B9 | C31: 8 | D31: 8 | E31: =IF(OR(A31="",D31="",D31=0),"",MIN(C31/D31*4,4)) | F31: 10 | G31: 10 | H31: =IF(OR(A31="",G31="",G31=0),"",MIN(F31/G31*4,4)) | I31: 6 | J31: 6 | K31: =IF(OR(A31="",J31="",J31=0),"",MIN(I31/J31*4,4)) | L31: 10 | M31: 10 | N31: =IF(OR(A31="",M31="",M31=0),"",MIN(L31/M31*4,4)) | O31: 4 | P31: 4 | Q31: =IF(OR(A31="",P31="",P31=0),"",MIN(O31/P31*4,4)) | R31: =IF(A31="","",SUM(E31,H31,K31,N31,Q31)) | S31: =IF(R31="","",_xlfn.IFS(R31>=18,"S",R31>=16,"A",R31>=14,"B",R31>=11,"C",TRUE,"D"))
A32: =IF(A10="","",A10) | B32: =B10 | C32: 7 | D32: 8 | E32: =IF(OR(A32="",D32="",D32=0),"",MIN(C32/D32*4,4)) | F32: 9 | G32: 10 | H32: =IF(OR(A32="",G32="",G32=0),"",MIN(F32/G32*4,4)) | I32: 5 | J32: 6 | K32: =IF(OR(A32="",J32="",J32=0),"",MIN(I32/J32*4,4)) | L32: 9 | M32: 10 | N32: =IF(OR(A32="",M32="",M32=0),"",MIN(L32/M32*4,4)) | O32: 4 | P32: 4 | Q32: =IF(OR(A32="",P32="",P32=0),"",MIN(O32/P32*4,4)) | R32: =IF(A32="","",SUM(E32,H32,K32,N32,Q32)) | S32: =IF(R32="","",_xlfn.IFS(R32>=18,"S",R32>=16,"A",R32>=14,"B",R32>=11,"C",TRUE,"D"))
A33: =IF(A11="","",A11) | B33: =B11 | C33: 7 | D33: 8 | E33: =IF(OR(A33="",D33="",D33=0),"",MIN(C33/D33*4,4)) | F33: 8 | G33: 10 | H33: =IF(OR(A33="",G33="",G33=0),"",MIN(F33/G33*4,4)) | I33: 5 | J33: 6 | K33: =IF(OR(A33="",J33="",J33=0),"",MIN(I33/J33*4,4)) | L33: 8 | M33: 10 | N33: =IF(OR(A33="",M33="",M33=0),"",MIN(L33/M33*4,4)) | O33: 3 | P33: 4 | Q33: =IF(OR(A33="",P33="",P33=0),"",MIN(O33/P33*4,4)) | R33: =IF(A33="","",SUM(E33,H33,K33,N33,Q33)) | S33: =IF(R33="","",_xlfn.IFS(R33>=18,"S",R33>=16,"A",R33>=14,"B",R33>=11,"C",TRUE,"D"))
A34: =IF(A12="","",A12) | B34: =B12 | C34: 6 | D34: 8 | E34: =IF(OR(A34="",D34="",D34=0),"",MIN(C34/D34*4,4)) | F34: 7 | G34: 10 | H34: =IF(OR(A34="",G34="",G34=0),"",MIN(F34/G34*4,4)) | I34: 4 | J34: 6 | K34: =IF(OR(A34="",J34="",J34=0),"",MIN(I34/J34*4,4)) | L34: 7 | M34: 10 | N34: =IF(OR(A34="",M34="",M34=0),"",MIN(L34/M34*4,4)) | O34: 3 | P34: 4 | Q34: =IF(OR(A34="",P34="",P34=0),"",MIN(O34/P34*4,4)) | R34: =IF(A34="","",SUM(E34,H34,K34,N34,Q34)) | S34: =IF(R34="","",_xlfn.IFS(R34>=18,"S",R34>=16,"A",R34>=14,"B",R34>=11,"C",TRUE,"D"))
A35: =IF(A13="","",A13) | B35: =B13 | C35: 5 | D35: 8 | E35: =IF(OR(A35="",D35="",D35=0),"",MIN(C35/D35*4,4)) | F35: 7 | G35: 10 | H35: =IF(OR(A35="",G35="",G35=0),"",MIN(F35/G35*4,4)) | I35: 4 | J35: 6 | K35: =IF(OR(A35="",J35="",J35=0),"",MIN(I35/J35*4,4)) | L35: 7 | M35: 10 | N35: =IF(OR(A35="",M35="",M35=0),"",MIN(L35/M35*4,4)) | O35: 3 | P35: 4 | Q35: =IF(OR(A35="",P35="",P35=0),"",MIN(O35/P35*4,4)) | R35: =IF(A35="","",SUM(E35,H35,K35,N35,Q35)) | S35: =IF(R35="","",_xlfn.IFS(R35>=18,"S",R35>=16,"A",R35>=14,"B",R35>=11,"C",TRUE,"D"))
A36: =IF(A14="","",A14) | B36: =B14 | C36: 5 | D36: 8 | E36: =IF(OR(A36="",D36="",D36=0),"",MIN(C36/D36*4,4)) | F36: 6 | G36: 10 | H36: =IF(OR(A36="",G36="",G36=0),"",MIN(F36/G36*4,4)) | I36: 3 | J36: 6 | K36: =IF(OR(A36="",J36="",J36=0),"",MIN(I36/J36*4,4)) | L36: 6 | M36: 10 | N36: =IF(OR(A36="",M36="",M36=0),"",MIN(L36/M36*4,4)) | O36: 2 | P36: 4 | Q36: =IF(OR(A36="",P36="",P36=0),"",MIN(O36/P36*4,4)) | R36: =IF(A36="","",SUM(E36,H36,K36,N36,Q36)) | S36: =IF(R36="","",_xlfn.IFS(R36>=18,"S",R36>=16,"A",R36>=14,"B",R36>=11,"C",TRUE,"D"))
